Workbook
Name MF_SchemeList: MF_Master!$B$4:INDEX(MF_Master!$B:$B,COUNTA(MF_Master!$B:$B)+2)
Name Stock_NameList: Stock_Master!$B$4:INDEX(Stock_Master!$B:$B,COUNTA(Stock_Master!$B:$B)+2)

Sheet Dashboard
A1: FAMILY PORTFOLIO — NET WORTH TRACKER
A2: As on | B2: =TODAY() -> 46217
A3: Family net worth | B3: =G16 -> 3259060.4 | D3: Inflation % p.a. | E3: 7
A4: Portfolio XIRR | B4: 0.067620969 | D4: Real return | E4: =IF(B4="","",(1+B4)/(1+E3/100)-1) -> -0.0022233931 | F4: =IF(B4="","",IF(B4>E3/100,"Beats inflation ✓","Below inflation ✗")) -> Below inflation ✗
A5: Person | B5: Equity | C5: Mutual Funds | D5: Fixed Deposits | E5: PPF | F5: Bonds | G5: Total
A6: Amit | B6: =IF($A6="","",SUMIFS(Equity!$I:$I,Equity!$A:$A,$A6)) -> 283200 | C6: =IF($A6="","",SUMIFS(MutualFunds!$I:$I,MutualFunds!$A:$A,$A6)) -> 65680.226 | D6: =IF($A6="","",SUMIFS(FixedDeposits!$I:$I,FixedDeposits!$A:$A,$A6)) -> 587277.98 | E6: =IF($A6="","",SUMIFS(PPF!$D:$D,PPF!$A:$A,$A6)) -> 425000 | F6: =IF($A6="","",SUMIFS(Bonds!$K:$K,Bonds!$A:$A,$A6)) -> 0 | G6: =IF($A6="","",SUM(B6:F6)) -> 1361158.2
A7: Priya | B7: =IF($A7="","",SUMIFS(Equity!$I:$I,Equity!$A:$A,$A7)) -> 222950 | C7: =IF($A7="","",SUMIFS(MutualFunds!$I:$I,MutualFunds!$A:$A,$A7)) -> 171733.97 | D7: =IF($A7="","",SUMIFS(FixedDeposits!$I:$I,FixedDeposits!$A:$A,$A7)) -> 0 | E7: =IF($A7="","",SUMIFS(PPF!$D:$D,PPF!$A:$A,$A7)) -> 860000 | F7: =IF($A7="","",SUMIFS(Bonds!$K:$K,Bonds!$A:$A,$A7)) -> 0 | G7: =IF($A7="","",SUM(B7:F7)) -> 1254684
A8: Rahul | B8: =IF($A8="","",SUMIFS(Equity!$I:$I,Equity!$A:$A,$A8)) -> 260600 | C8: =IF($A8="","",SUMIFS(MutualFunds!$I:$I,MutualFunds!$A:$A,$A8)) -> 0 | D8: =IF($A8="","",SUMIFS(FixedDeposits!$I:$I,FixedDeposits!$A:$A,$A8)) -> 331868.19 | E8: =IF($A8="","",SUMIFS(PPF!$D:$D,PPF!$A:$A,$A8)) -> 0 | F8: =IF($A8="","",SUMIFS(Bonds!$K:$K,Bonds!$A:$A,$A8)) -> 50750 | G8: =IF($A8="","",SUM(B8:F8)) -> 643218.19
B9: =IF($A9="","",SUMIFS(Equity!$I:$I,Equity!$A:$A,$A9)) | C9: =IF($A9="","",SUMIFS(MutualFunds!$I:$I,MutualFunds!$A:$A,$A9)) | D9: =IF($A9="","",SUMIFS(FixedDeposits!$I:$I,FixedDeposits!$A:$A,$A9)) | E9: =IF($A9="","",SUMIFS(PPF!$D:$D,PPF!$A:$A,$A9)) | F9: =IF($A9="","",SUMIFS(Bonds!$K:$K,Bonds!$A:$A,$A9)) | G9: =IF($A9="","",SUM(B9:F9))
B10: =IF($A10="","",SUMIFS(Equity!$I:$I,Equity!$A:$A,$A10)) | C10: =IF($A10="","",SUMIFS(MutualFunds!$I:$I,MutualFunds!$A:$A,$A10)) | D10: =IF($A10="","",SUMIFS(FixedDeposits!$I:$I,FixedDeposits!$A:$A,$A10)) | E10: =IF($A10="","",SUMIFS(PPF!$D:$D,PPF!$A:$A,$A10)) | F10: =IF($A10="","",SUMIFS(Bonds!$K:$K,Bonds!$A:$A,$A10)) | G10: =IF($A10="","",SUM(B10:F10))
B11: =IF($A11="","",SUMIFS(Equity!$I:$I,Equity!$A:$A,$A11)) | C11: =IF($A11="","",SUMIFS(MutualFunds!$I:$I,MutualFunds!$A:$A,$A11)) | D11: =IF($A11="","",SUMIFS(FixedDeposits!$I:$I,FixedDeposits!$A:$A,$A11)) | E11: =IF($A11="","",SUMIFS(PPF!$D:$D,PPF!$A:$A,$A11)) | F11: =IF($A11="","",SUMIFS(Bonds!$K:$K,Bonds!$A:$A,$A11)) | G11: =IF($A11="","",SUM(B11:F11))
B12: =IF($A12="","",SUMIFS(Equity!$I:$I,Equity!$A:$A,$A12)) | C12: =IF($A12="","",SUMIFS(MutualFunds!$I:$I,MutualFunds!$A:$A,$A12)) | D12: =IF($A12="","",SUMIFS(FixedDeposits!$I:$I,FixedDeposits!$A:$A,$A12)) | E12: =IF($A12="","",SUMIFS(PPF!$D:$D,PPF!$A:$A,$A12)) | F12: =IF($A12="","",SUMIFS(Bonds!$K:$K,Bonds!$A:$A,$A12)) | G12: =IF($A12="","",SUM(B12:F12))
B13: =IF($A13="","",SUMIFS(Equity!$I:$I,Equity!$A:$A,$A13)) | C13: =IF($A13="","",SUMIFS(MutualFunds!$I:$I,MutualFunds!$A:$A,$A13)) | D13: =IF($A13="","",SUMIFS(FixedDeposits!$I:$I,FixedDeposits!$A:$A,$A13)) | E13: =IF($A13="","",SUMIFS(PPF!$D:$D,PPF!$A:$A,$A13)) | F13: =IF($A13="","",SUMIFS(Bonds!$K:$K,Bonds!$A:$A,$A13)) | G13: =IF($A13="","",SUM(B13:F13))
B14: =IF($A14="","",SUMIFS(Equity!$I:$I,Equity!$A:$A,$A14)) | C14: =IF($A14="","",SUMIFS(MutualFunds!$I:$I,MutualFunds!$A:$A,$A14)) | D14: =IF($A14="","",SUMIFS(FixedDeposits!$I:$I,FixedDeposits!$A:$A,$A14)) | E14: =IF($A14="","",SUMIFS(PPF!$D:$D,PPF!$A:$A,$A14)) | F14: =IF($A14="","",SUMIFS(Bonds!$K:$K,Bonds!$A:$A,$A14)) | G14: =IF($A14="","",SUM(B14:F14))
B15: =IF($A15="","",SUMIFS(Equity!$I:$I,Equity!$A:$A,$A15)) | C15: =IF($A15="","",SUMIFS(MutualFunds!$I:$I,MutualFunds!$A:$A,$A15)) | D15: =IF($A15="","",SUMIFS(FixedDeposits!$I:$I,FixedDeposits!$A:$A,$A15)) | E15: =IF($A15="","",SUMIFS(PPF!$D:$D,PPF!$A:$A,$A15)) | F15: =IF($A15="","",SUMIFS(Bonds!$K:$K,Bonds!$A:$A,$A15)) | G15: =IF($A15="","",SUM(B15:F15))
A16: TOTAL | B16: =SUM(B6:B15) -> 766750 | C16: =SUM(C6:C15) -> 237414.19 | D16: =SUM(D6:D15) -> 919146.17 | E16: =SUM(E6:E15) -> 1285000 | F16: =SUM(F6:F15) -> 50750 | G16: =SUM(G6:G15) -> 3259060.4
A18: Allocation by asset class
A19: Asset class | B19: Value | C19: XIRR
A20: Equity | B20: =B16 -> 766750 | C20: 0.066436552
A21: Mutual Funds | B21: =C16 -> 237414.19 | C21: 0.087670606
A22: Fixed Deposits | B22: =D16 -> 919146.17 | C22: 0.072140147
A23: PPF | B23: =E16 -> 1285000 | C23: 0.071
A24: Bonds | B24: =F16 -> 50750 | C24: 0.0059830784

Sheet Projection
A1: CORPUS PROJECTION — NEXT 20 YEARS
A2: Today's corpus compounding at the portfolio XIRR vs plain inflation. Assumes a constant return and no future contributions. Edit inflation on the Dashboard (yellow cell); the updaters refresh the XIRR.
A3: Year | B3: Corpus @ portfolio XIRR | C3: Corpus growing at inflation | D3: Real corpus (today's money)
A4: =YEAR(TODAY())+0 -> 2026 | B4: =Dashboard!$B$3*(1+Dashboard!$B$4)^0 -> 3259060.4 | C4: =Dashboard!$B$3*(1+Dashboard!$E$3/100)^0 -> 3259060.4 | D4: =B4/(1+Dashboard!$E$3/100)^0 -> 3259060.4
A5: =YEAR(TODAY())+1 -> 2027 | B5: =Dashboard!$B$3*(1+Dashboard!$B$4)^1 -> 3479441.2 | C5: =Dashboard!$B$3*(1+Dashboard!$E$3/100)^1 -> 3487194.6 | D5: =B5/(1+Dashboard!$E$3/100)^1 -> 3251814.2
A6: =YEAR(TODAY())+2 -> 2028 | B6: =Dashboard!$B$3*(1+Dashboard!$B$4)^2 -> 3714724.4 | C6: =Dashboard!$B$3*(1+Dashboard!$E$3/100)^2 -> 3731298.2 | D6: =B6/(1+Dashboard!$E$3/100)^2 -> 3244584.1
A7: =YEAR(TODAY())+3 -> 2029 | B7: =Dashboard!$B$3*(1+Dashboard!$B$4)^3 -> 3965917.6 | C7: =Dashboard!$B$3*(1+Dashboard!$E$3/100)^3 -> 3992489.1 | D7: =B7/(1+Dashboard!$E$3/100)^3 -> 3237370.1
A8: =YEAR(TODAY())+4 -> 2030 | B8: =Dashboard!$B$3*(1+Dashboard!$B$4)^4 -> 4234096.8 | C8: =Dashboard!$B$3*(1+Dashboard!$E$3/100)^4 -> 4271963.3 | D8: =B8/(1+Dashboard!$E$3/100)^4 -> 3230172.2
A9: =YEAR(TODAY())+5 -> 2031 | B9: =Dashboard!$B$3*(1+Dashboard!$B$4)^5 -> 4520410.6 | C9: =Dashboard!$B$3*(1+Dashboard!$E$3/100)^5 -> 4571000.8 | D9: =B9/(1+Dashboard!$E$3/100)^5 -> 3222990.3
A10: =YEAR(TODAY())+6 -> 2032 | B10: =Dashboard!$B$3*(1+Dashboard!$B$4)^6 -> 4826085.1 | C10: =Dashboard!$B$3*(1+Dashboard!$E$3/100)^6 -> 4890970.8 | D10: =B10/(1+Dashboard!$E$3/100)^6 -> 3215824.3
A11: =YEAR(TODAY())+7 -> 2033 | B11: =Dashboard!$B$3*(1+Dashboard!$B$4)^7 -> 5152429.7 | C11: =Dashboard!$B$3*(1+Dashboard!$E$3/100)^7 -> 5233338.8 | D11: =B11/(1+Dashboard!$E$3/100)^7 -> 3208674.2
A12: =YEAR(TODAY())+8 -> 2034 | B12: =Dashboard!$B$3*(1+Dashboard!$B$4)^8 -> 5500842 | C12: =Dashboard!$B$3*(1+Dashboard!$E$3/100)^8 -> 5599672.5 | D12: =B12/(1+Dashboard!$E$3/100)^8 -> 3201540.1
A13: =YEAR(TODAY())+9 -> 2035 | B13: =Dashboard!$B$3*(1+Dashboard!$B$4)^9 -> 5872814.2 | C13: =Dashboard!$B$3*(1+Dashboard!$E$3/100)^9 -> 5991649.6 | D13: =B13/(1+Dashboard!$E$3/100)^9 -> 3194421.8
A14: =YEAR(TODAY())+10 -> 2036 | B14: =Dashboard!$B$3*(1+Dashboard!$B$4)^10 -> 6269939.6 | C14: =Dashboard!$B$3*(1+Dashboard!$E$3/100)^10 -> 6411065 | D14: =B14/(1+Dashboard!$E$3/100)^10 -> 3187319.4
A15: =YEAR(TODAY())+11 -> 2037 | B15: =Dashboard!$B$3*(1+Dashboard!$B$4)^11 -> 6693919 | C15: =Dashboard!$B$3*(1+Dashboard!$E$3/100)^11 -> 6859839.6 | D15: =B15/(1+Dashboard!$E$3/100)^11 -> 3180232.7
A16: =YEAR(TODAY())+12 -> 2038 | B16: =Dashboard!$B$3*(1+Dashboard!$B$4)^12 -> 7146568.3 | C16: =Dashboard!$B$3*(1+Dashboard!$E$3/100)^12 -> 7340028.3 | D16: =B16/(1+Dashboard!$E$3/100)^12 -> 3173161.8
A17: =YEAR(TODAY())+13 -> 2039 | B17: =Dashboard!$B$3*(1+Dashboard!$B$4)^13 -> 7629826.2 | C17: =Dashboard!$B$3*(1+Dashboard!$E$3/100)^13 -> 7853830.3 | D17: =B17/(1+Dashboard!$E$3/100)^13 -> 3166106.6
A18: =YEAR(TODAY())+14 -> 2040 | B18: =Dashboard!$B$3*(1+Dashboard!$B$4)^14 -> 8145762.4 | C18: =Dashboard!$B$3*(1+Dashboard!$E$3/100)^14 -> 8403598.5 | D18: =B18/(1+Dashboard!$E$3/100)^14 -> 3159067.1
A19: =YEAR(TODAY())+15 -> 2041 | B19: =Dashboard!$B$3*(1+Dashboard!$B$4)^15 -> 8696586.8 | C19: =Dashboard!$B$3*(1+Dashboard!$E$3/100)^15 -> 8991850.3 | D19: =B19/(1+Dashboard!$E$3/100)^15 -> 3152043.3
A20: =YEAR(TODAY())+16 -> 2042 | B20: =Dashboard!$B$3*(1+Dashboard!$B$4)^16 -> 9284658.4 | C20: =Dashboard!$B$3*(1+Dashboard!$E$3/100)^16 -> 9621279.9 | D20: =B20/(1+Dashboard!$E$3/100)^16 -> 3145035
A21: =YEAR(TODAY())+17 -> 2043 | B21: =Dashboard!$B$3*(1+Dashboard!$B$4)^17 -> 9912496 | C21: =Dashboard!$B$3*(1+Dashboard!$E$3/100)^17 -> 10294769 | D21: =B21/(1+Dashboard!$E$3/100)^17 -> 3138042.4
A22: =YEAR(TODAY())+18 -> 2044 | B22: =Dashboard!$B$3*(1+Dashboard!$B$4)^18 -> 10582789 | C22: =Dashboard!$B$3*(1+Dashboard!$E$3/100)^18 -> 11015403 | D22: =B22/(1+Dashboard!$E$3/100)^18 -> 3131065.3
A23: =YEAR(TODAY())+19 -> 2045 | B23: =Dashboard!$B$3*(1+Dashboard!$B$4)^19 -> 11298407 | C23: =Dashboard!$B$3*(1+Dashboard!$E$3/100)^19 -> 11786482 | D23: =B23/(1+Dashboard!$E$3/100)^19 -> 3124103.7
A24: =YEAR(TODAY())+20 -> 2046 | B24: =Dashboard!$B$3*(1+Dashboard!$B$4)^20 -> 12062416 | C24: =Dashboard!$B$3*(1+Dashboard!$E$3/100)^20 -> 12611535 | D24: =B24/(1+Dashboard!$E$3/100)^20 -> 3117157.6
A27: HOW TO READ THIS SHEET (in plain words)
A28: Your family's money today (the Dashboard net worth) is shown on three paths:
A29: 1. Corpus @ portfolio XIRR — what your money can GROW TO if it keeps earning the
A30: same yearly return it earns today (the 'Portfolio XIRR' on the Dashboard).
A31: 2. Corpus growing at inflation — what the same money must become JUST TO KEEP UP
A32: with rising prices (the yellow 'Inflation %' cell on the Dashboard, normally 7).
A33: 3. Real corpus (today’s money) — the first path converted back into today’s prices:
A34: what that future amount will actually feel like when you spend it.
A35: Simple rule: if the BLUE line (your portfolio) stays above the RED line (inflation),
A36: you are beating inflation and getting richer in real terms. If it dips below, your
A37: money is still growing but it quietly buys less every year.
A38: Example: at 7% inflation, 1 crore received 20 years from now buys only what roughly
... A40: Try it: change the yellow inflation cell on the Dashboard — the lines move instantly.

Sheet Amit
A1: Amit — PORTFOLIO
A2: Owner | B2: Amit
A3: Net worth | B3: =B11 -> 1361158.2
A5: Asset class | B5: Value | C5: # holdings
A6: Equity | B6: =SUMIFS(Equity!$I:$I,Equity!$A:$A,$B$2) -> 283200 | C6: =COUNTIF(Equity!$A:$A,$B$2) -> 4
A7: Mutual Funds | B7: =SUMIFS(MutualFunds!$I:$I,MutualFunds!$A:$A,$B$2) -> 65680.226 | C7: =COUNTIF(MutualFunds!$A:$A,$B$2) -> 1
A8: Fixed Deposits | B8: =SUMIFS(FixedDeposits!$I:$I,FixedDeposits!$A:$A,$B$2) -> 587277.98 | C8: =COUNTIF(FixedDeposits!$A:$A,$B$2) -> 1
A9: PPF | B9: =SUMIFS(PPF!$D:$D,PPF!$A:$A,$B$2) -> 425000 | C9: =COUNTIF(PPF!$A:$A,$B$2) -> 1
A10: Bonds | B10: =SUMIFS(Bonds!$K:$K,Bonds!$A:$A,$B$2) -> 0 | C10: =COUNTIF(Bonds!$A:$A,$B$2) -> 0
A11: Total | B11: =SUM(B6:B10) -> 1361158.2 | C11: =SUM(C6:C10) -> 7
A14: EQUITY
A15: ISIN | B15: Scrip | C15: Qty | D15: Avg cost | E15: Cur. val | F15: Net chg. | G15: XIRR
A16: =IFERROR(INDEX(Equity!$B:$B,MATCH($B$2&"#"&1,Equity!$P:$P,0)),"") -> INE002A01018 | B16: =IFERROR(INDEX(Equity!$C:$C,MATCH($B$2&"#"&1,Equity!$P:$P,0)),"") -> RELIANCE INDUSTRIES LIMITED EQ | C16: =IFERROR(INDEX(Equity!$D:$D,MATCH($B$2&"#"&1,Equity!$P:$P,0)),"") -> 50 | D16: =IFERROR(INDEX(Equity!$E:$E,MATCH($B$2&"#"&1,Equity!$P:$P,0)),"") -> 964.9 | E16: =IFERROR(INDEX(Equity!$I:$I,MATCH($B$2&"#"&1,Equity!$P:$P,0)),"") -> 76000 | F16: =IFERROR(INDEX(Equity!$K:$K,MATCH($B$2&"#"&1,Equity!$P:$P,0)),"") -> 27755 | G16: =IFERROR(INDEX(Equity!$N:$N,MATCH($B$2&"#"&1,Equity!$P:$P,0)),"") -> 0.055220257
A17: =IFERROR(INDEX(Equity!$B:$B,MATCH($B$2&"#"&2,Equity!$P:$P,0)),"") -> INE467B01029 | B17: =IFERROR(INDEX(Equity!$C:$C,MATCH($B$2&"#"&2,Equity!$P:$P,0)),"") -> TATA CONSULTANCY SERVICES LIMITED EQ | C17: =IFERROR(INDEX(Equity!$D:$D,MATCH($B$2&"#"&2,Equity!$P:$P,0)),"") -> 12 | D17: =IFERROR(INDEX(Equity!$E:$E,MATCH($B$2&"#"&2,Equity!$P:$P,0)),"") -> 2916.05 | E17: =IFERROR(INDEX(Equity!$I:$I,MATCH($B$2&"#"&2,Equity!$P:$P,0)),"") -> 41400 | F17: =IFERROR(INDEX(Equity!$K:$K,MATCH($B$2&"#"&2,Equity!$P:$P,0)),"") -> 6407.4 | G17: =IFERROR(INDEX(Equity!$N:$N,MATCH($B$2&"#"&2,Equity!$P:$P,0)),"") -> 0.020086519
A18: =IFERROR(INDEX(Equity!$B:$B,MATCH($B$2&"#"&3,Equity!$P:$P,0)),"") -> INE009A01021 | B18: =IFERROR(INDEX(Equity!$C:$C,MATCH($B$2&"#"&3,Equity!$P:$P,0)),"") -> INFOSYS LIMITED EQ | C18: =IFERROR(INDEX(Equity!$D:$D,MATCH($B$2&"#"&3,Equity!$P:$P,0)),"") -> 40 | D18: =IFERROR(INDEX(Equity!$E:$E,MATCH($B$2&"#"&3,Equity!$P:$P,0)),"") -> 1173.85 | E18: =IFERROR(INDEX(Equity!$I:$I,MATCH($B$2&"#"&3,Equity!$P:$P,0)),"") -> 64400 | F18: =IFERROR(INDEX(Equity!$K:$K,MATCH($B$2&"#"&3,Equity!$P:$P,0)),"") -> 17446 | G18: =IFERROR(INDEX(Equity!$N:$N,MATCH($B$2&"#"&3,Equity!$P:$P,0)),"") -> 0.038075757
A19: =IFERROR(INDEX(Equity!$B:$B,MATCH($B$2&"#"&4,Equity!$P:$P,0)),"") -> INE040A01034 | B19: =IFERROR(INDEX(Equity!$C:$C,MATCH($B$2&"#"&4,Equity!$P:$P,0)),"") -> HDFC BANK LIMITED EQ | C19: =IFERROR(INDEX(Equity!$D:$D,MATCH($B$2&"#"&4,Equity!$P:$P,0)),"") -> 60 | D19: =IFERROR(INDEX(Equity!$E:$E,MATCH($B$2&"#"&4,Equity!$P:$P,0)),"") -> 1076 | E19: =IFERROR(INDEX(Equity!$I:$I,MATCH($B$2&"#"&4,Equity!$P:$P,0)),"") -> 101400 | F19: =IFERROR(INDEX(Equity!$K:$K,MATCH($B$2&"#"&4,Equity!$P:$P,0)),"") -> 36840 | G19: =IFERROR(INDEX(Equity!$N:$N,MATCH($B$2&"#"&4,Equity!$P:$P,0)),"") -> 0.054850508
A20: =IFERROR(INDEX(Equity!$B:$B,MATCH($B$2&"#"&5,Equity!$P:$P,0)),"") | B20: =IFERROR(INDEX(Equity!$C:$C,MATCH($B$2&"#"&5,Equity!$P:$P,0)),"") | C20: =IFERROR(INDEX(Equity!$D:$D,MATCH($B$2&"#"&5,Equity!$P:$P,0)),"") | D20: =IFERROR(INDEX(Equity!$E:$E,MATCH($B$2&"#"&5,Equity!$P:$P,0)),"") | E20: =IFERROR(INDEX(Equity!$I:$I,MATCH($B$2&"#"&5,Equity!$P:$P,0)),"") | F20: =IFERROR(INDEX(Equity!$K:$K,MATCH($B$2&"#"&5,Equity!$P:$P,0)),"") | G20: =IFERROR(INDEX(Equity!$N:$N,MATCH($B$2&"#"&5,Equity!$P:$P,0)),"")
A21: =IFERROR(INDEX(Equity!$B:$B,MATCH($B$2&"#"&6,Equity!$P:$P,0)),"") | B21: =IFERROR(INDEX(Equity!$C:$C,MATCH($B$2&"#"&6,Equity!$P:$P,0)),"") | C21: =IFERROR(INDEX(Equity!$D:$D,MATCH($B$2&"#"&6,Equity!$P:$P,0)),"") | D21: =IFERROR(INDEX(Equity!$E:$E,MATCH($B$2&"#"&6,Equity!$P:$P,0)),"") | E21: =IFERROR(INDEX(Equity!$I:$I,MATCH($B$2&"#"&6,Equity!$P:$P,0)),"") | F21: =IFERROR(INDEX(Equity!$K:$K,MATCH($B$2&"#"&6,Equity!$P:$P,0)),"") | G21: =IFERROR(INDEX(Equity!$N:$N,MATCH($B$2&"#"&6,Equity!$P:$P,0)),"")
A22: =IFERROR(INDEX(Equity!$B:$B,MATCH($B$2&"#"&7,Equity!$P:$P,0)),"") | B22: =IFERROR(INDEX(Equity!$C:$C,MATCH($B$2&"#"&7,Equity!$P:$P,0)),"") | C22: =IFERROR(INDEX(Equity!$D:$D,MATCH($B$2&"#"&7,Equity!$P:$P,0)),"") | D22: =IFERROR(INDEX(Equity!$E:$E,MATCH($B$2&"#"&7,Equity!$P:$P,0)),"") | E22: =IFERROR(INDEX(Equity!$I:$I,MATCH($B$2&"#"&7,Equity!$P:$P,0)),"") | F22: =IFERROR(INDEX(Equity!$K:$K,MATCH($B$2&"#"&7,Equity!$P:$P,0)),"") | G22: =IFERROR(INDEX(Equity!$N:$N,MATCH($B$2&"#"&7,Equity!$P:$P,0)),"")
A23: =IFERROR(INDEX(Equity!$B:$B,MATCH($B$2&"#"&8,Equity!$P:$P,0)),"") | B23: =IFERROR(INDEX(Equity!$C:$C,MATCH($B$2&"#"&8,Equity!$P:$P,0)),"") | C23: =IFERROR(INDEX(Equity!$D:$D,MATCH($B$2&"#"&8,Equity!$P:$P,0)),"") | D23: =IFERROR(INDEX(Equity!$E:$E,MATCH($B$2&"#"&8,Equity!$P:$P,0)),"") | E23: =IFERROR(INDEX(Equity!$I:$I,MATCH($B$2&"#"&8,Equity!$P:$P,0)),"") | F23: =IFERROR(INDEX(Equity!$K:$K,MATCH($B$2&"#"&8,Equity!$P:$P,0)),"") | G23: =IFERROR(INDEX(Equity!$N:$N,MATCH($B$2&"#"&8,Equity!$P:$P,0)),"")
A24: =IFERROR(INDEX(Equity!$B:$B,MATCH($B$2&"#"&9,Equity!$P:$P,0)),"") | B24: =IFERROR(INDEX(Equity!$C:$C,MATCH($B$2&"#"&9,Equity!$P:$P,0)),"") | C24: =IFERROR(INDEX(Equity!$D:$D,MATCH($B$2&"#"&9,Equity!$P:$P,0)),"") | D24: =IFERROR(INDEX(Equity!$E:$E,MATCH($B$2&"#"&9,Equity!$P:$P,0)),"") | E24: =IFERROR(INDEX(Equity!$I:$I,MATCH($B$2&"#"&9,Equity!$P:$P,0)),"") | F24: =IFERROR(INDEX(Equity!$K:$K,MATCH($B$2&"#"&9,Equity!$P:$P,0)),"") | G24: =IFERROR(INDEX(Equity!$N:$N,MATCH($B$2&"#"&9,Equity!$P:$P,0)),"")
A25: =IFERROR(INDEX(Equity!$B:$B,MATCH($B$2&"#"&10,Equity!$P:$P,0)),"") | B25: =IFERROR(INDEX(Equity!$C:$C,MATCH($B$2&"#"&10,Equity!$P:$P,0)),"") | C25: =IFERROR(INDEX(Equity!$D:$D,MATCH($B$2&"#"&10,Equity!$P:$P,0)),"") | D25: =IFERROR(INDEX(Equity!$E:$E,MATCH($B$2&"#"&10,Equity!$P:$P,0)),"") | E25: =IFERROR(INDEX(Equity!$I:$I,MATCH($B$2&"#"&10,Equity!$P:$P,0)),"") | F25: =IFERROR(INDEX(Equity!$K:$K,MATCH($B$2&"#"&10,Equity!$P:$P,0)),"") | G25: =IFERROR(INDEX(Equity!$N:$N,MATCH($B$2&"#"&10,Equity!$P:$P,0)),"")
A26: =IFERROR(INDEX(Equity!$B:$B,MATCH($B$2&"#"&11,Equity!$P:$P,0)),"") | B26: =IFERROR(INDEX(Equity!$C:$C,MATCH($B$2&"#"&11,Equity!$P:$P,0)),"") | C26: =IFERROR(INDEX(Equity!$D:$D,MATCH($B$2&"#"&11,Equity!$P:$P,0)),"") | D26: =IFERROR(INDEX(Equity!$E:$E,MATCH($B$2&"#"&11,Equity!$P:$P,0)),"") | E26: =IFERROR(INDEX(Equity!$I:$I,MATCH($B$2&"#"&11,Equity!$P:$P,0)),"") | F26: =IFERROR(INDEX(Equity!$K:$K,MATCH($B$2&"#"&11,Equity!$P:$P,0)),"") | G26: =IFERROR(INDEX(Equity!$N:$N,MATCH($B$2&"#"&11,Equity!$P:$P,0)),"")
A27: =IFERROR(INDEX(Equity!$B:$B,MATCH($B$2&"#"&12,Equity!$P:$P,0)),"") | B27: =IFERROR(INDEX(Equity!$C:$C,MATCH($B$2&"#"&12,Equity!$P:$P,0)),"") | C27: =IFERROR(INDEX(Equity!$D:$D,MATCH($B$2&"#"&12,Equity!$P:$P,0)),"") | D27: =IFERROR(INDEX(Equity!$E:$E,MATCH($B$2&"#"&12,Equity!$P:$P,0)),"") | E27: =IFERROR(INDEX(Equity!$I:$I,MATCH($B$2&"#"&12,Equity!$P:$P,0)),"") | F27: =IFERROR(INDEX(Equity!$K:$K,MATCH($B$2&"#"&12,Equity!$P:$P,0)),"") | G27: =IFERROR(INDEX(Equity!$N:$N,MATCH($B$2&"#"&12,Equity!$P:$P,0)),"")
A28: =IFERROR(INDEX(Equity!$B:$B,MATCH($B$2&"#"&13,Equity!$P:$P,0)),"") | B28: =IFERROR(INDEX(Equity!$C:$C,MATCH($B$2&"#"&13,Equity!$P:$P,0)),"") | C28: =IFERROR(INDEX(Equity!$D:$D,MATCH($B$2&"#"&13,Equity!$P:$P,0)),"") | D28: =IFERROR(INDEX(Equity!$E:$E,MATCH($B$2&"#"&13,Equity!$P:$P,0)),"") | E28: =IFERROR(INDEX(Equity!$I:$I,MATCH($B$2&"#"&13,Equity!$P:$P,0)),"") | F28: =IFERROR(INDEX(Equity!$K:$K,MATCH($B$2&"#"&13,Equity!$P:$P,0)),"") | G28: =IFERROR(INDEX(Equity!$N:$N,MATCH($B$2&"#"&13,Equity!$P:$P,0)),"")
A29: =IFERROR(INDEX(Equity!$B:$B,MATCH($B$2&"#"&14,Equity!$P:$P,0)),"") | B29: =IFERROR(INDEX(Equity!$C:$C,MATCH($B$2&"#"&14,Equity!$P:$P,0)),"") | C29: =IFERROR(INDEX(Equity!$D:$D,MATCH($B$2&"#"&14,Equity!$P:$P,0)),"") | D29: =IFERROR(INDEX(Equity!$E:$E,MATCH($B$2&"#"&14,Equity!$P:$P,0)),"") | E29: =IFERROR(INDEX(Equity!$I:$I,MATCH($B$2&"#"&14,Equity!$P:$P,0)),"") | F29: =IFERROR(INDEX(Equity!$K:$K,MATCH($B$2&"#"&14,Equity!$P:$P,0)),"") | G29: =IFERROR(INDEX(Equity!$N:$N,MATCH($B$2&"#"&14,Equity!$P:$P,0)),"")
A30: =IFERROR(INDEX(Equity!$B:$B,MATCH($B$2&"#"&15,Equity!$P:$P,0)),"") | B30: =IFERROR(INDEX(Equity!$C:$C,MATCH($B$2&"#"&15,Equity!$P:$P,0)),"") | C30: =IFERROR(INDEX(Equity!$D:$D,MATCH($B$2&"#"&15,Equity!$P:$P,0)),"") | D30: =IFERROR(INDEX(Equity!$E:$E,MATCH($B$2&"#"&15,Equity!$P:$P,0)),"") | E30: =IFERROR(INDEX(Equity!$I:$I,MATCH($B$2&"#"&15,Equity!$P:$P,0)),"") | F30: =IFERROR(INDEX(Equity!$K:$K,MATCH($B$2&"#"&15,Equity!$P:$P,0)),"") | G30: =IFERROR(INDEX(Equity!$N:$N,MATCH($B$2&"#"&15,Equity!$P:$P,0)),"")
A31: =IFERROR(INDEX(Equity!$B:$B,MATCH($B$2&"#"&16,Equity!$P:$P,0)),"") | B31: =IFERROR(INDEX(Equity!$C:$C,MATCH($B$2&"#"&16,Equity!$P:$P,0)),"") | C31: =IFERROR(INDEX(Equity!$D:$D,MATCH($B$2&"#"&16,Equity!$P:$P,0)),"") | D31: =IFERROR(INDEX(Equity!$E:$E,MATCH($B$2&"#"&16,Equity!$P:$P,0)),"") | E31: =IFERROR(INDEX(Equity!$I:$I,MATCH($B$2&"#"&16,Equity!$P:$P,0)),"") | F31: =IFERROR(INDEX(Equity!$K:$K,MATCH($B$2&"#"&16,Equity!$P:$P,0)),"") | G31: =IFERROR(INDEX(Equity!$N:$N,MATCH($B$2&"#"&16,Equity!$P:$P,0)),"")
A32: =IFERROR(INDEX(Equity!$B:$B,MATCH($B$2&"#"&17,Equity!$P:$P,0)),"") | B32: =IFERROR(INDEX(Equity!$C:$C,MATCH($B$2&"#"&17,Equity!$P:$P,0)),"") | C32: =IFERROR(INDEX(Equity!$D:$D,MATCH($B$2&"#"&17,Equity!$P:$P,0)),"") | D32: =IFERROR(INDEX(Equity!$E:$E,MATCH($B$2&"#"&17,Equity!$P:$P,0)),"") | E32: =IFERROR(INDEX(Equity!$I:$I,MATCH($B$2&"#"&17,Equity!$P:$P,0)),"") | F32: =IFERROR(INDEX(Equity!$K:$K,MATCH($B$2&"#"&17,Equity!$P:$P,0)),"") | G32: =IFERROR(INDEX(Equity!$N:$N,MATCH($B$2&"#"&17,Equity!$P:$P,0)),"")
A33: =IFERROR(INDEX(Equity!$B:$B,MATCH($B$2&"#"&18,Equity!$P:$P,0)),"") | B33: =IFERROR(INDEX(Equity!$C:$C,MATCH($B$2&"#"&18,Equity!$P:$P,0)),"") | C33: =IFERROR(INDEX(Equity!$D:$D,MATCH($B$2&"#"&18,Equity!$P:$P,0)),"") | D33: =IFERROR(INDEX(Equity!$E:$E,MATCH($B$2&"#"&18,Equity!$P:$P,0)),"") | E33: =IFERROR(INDEX(Equity!$I:$I,MATCH($B$2&"#"&18,Equity!$P:$P,0)),"") | F33: =IFERROR(INDEX(Equity!$K:$K,MATCH($B$2&"#"&18,Equity!$P:$P,0)),"") | G33: =IFERROR(INDEX(Equity!$N:$N,MATCH($B$2&"#"&18,Equity!$P:$P,0)),"")
A34: =IFERROR(INDEX(Equity!$B:$B,MATCH($B$2&"#"&19,Equity!$P:$P,0)),"") | B34: =IFERROR(INDEX(Equity!$C:$C,MATCH($B$2&"#"&19,Equity!$P:$P,0)),"") | C34: =IFERROR(INDEX(Equity!$D:$D,MATCH($B$2&"#"&19,Equity!$P:$P,0)),"") | D34: =IFERROR(INDEX(Equity!$E:$E,MATCH($B$2&"#"&19,Equity!$P:$P,0)),"") | E34: =IFERROR(INDEX(Equity!$I:$I,MATCH($B$2&"#"&19,Equity!$P:$P,0)),"") | F34: =IFERROR(INDEX(Equity!$K:$K,MATCH($B$2&"#"&19,Equity!$P:$P,0)),"") | G34: =IFERROR(INDEX(Equity!$N:$N,MATCH($B$2&"#"&19,Equity!$P:$P,0)),"")
A35: =IFERROR(INDEX(Equity!$B:$B,MATCH($B$2&"#"&20,Equity!$P:$P,0)),"") | B35: =IFERROR(INDEX(Equity!$C:$C,MATCH($B$2&"#"&20,Equity!$P:$P,0)),"") | C35: =IFERROR(INDEX(Equity!$D:$D,MATCH($B$2&"#"&20,Equity!$P:$P,0)),"") | D35: =IFERROR(INDEX(Equity!$E:$E,MATCH($B$2&"#"&20,Equity!$P:$P,0)),"") | E35: =IFERROR(INDEX(Equity!$I:$I,MATCH($B$2&"#"&20,Equity!$P:$P,0)),"") | F35: =IFERROR(INDEX(Equity!$K:$K,MATCH($B$2&"#"&20,Equity!$P:$P,0)),"") | G35: =IFERROR(INDEX(Equity!$N:$N,MATCH($B$2&"#"&20,Equity!$P:$P,0)),"")
A36: =IFERROR(INDEX(Equity!$B:$B,MATCH($B$2&"#"&21,Equity!$P:$P,0)),"") | B36: =IFERROR(INDEX(Equity!$C:$C,MATCH($B$2&"#"&21,Equity!$P:$P,0)),"") | C36: =IFERROR(INDEX(Equity!$D:$D,MATCH($B$2&"#"&21,Equity!$P:$P,0)),"") | D36: =IFERROR(INDEX(Equity!$E:$E,MATCH($B$2&"#"&21,Equity!$P:$P,0)),"") | E36: =IFERROR(INDEX(Equity!$I:$I,MATCH($B$2&"#"&21,Equity!$P:$P,0)),"") | F36: =IFERROR(INDEX(Equity!$K:$K,MATCH($B$2&"#"&21,Equity!$P:$P,0)),"") | G36: =IFERROR(INDEX(Equity!$N:$N,MATCH($B$2&"#"&21,Equity!$P:$P,0)),"")
A37: =IFERROR(INDEX(Equity!$B:$B,MATCH($B$2&"#"&22,Equity!$P:$P,0)),"") | B37: =IFERROR(INDEX(Equity!$C:$C,MATCH($B$2&"#"&22,Equity!$P:$P,0)),"") | C37: =IFERROR(INDEX(Equity!$D:$D,MATCH($B$2&"#"&22,Equity!$P:$P,0)),"") | D37: =IFERROR(INDEX(Equity!$E:$E,MATCH($B$2&"#"&22,Equity!$P:$P,0)),"") | E37: =IFERROR(INDEX(Equity!$I:$I,MATCH($B$2&"#"&22,Equity!$P:$P,0)),"") | F37: =IFERROR(INDEX(Equity!$K:$K,MATCH($B$2&"#"&22,Equity!$P:$P,0)),"") | G37: =IFERROR(INDEX(Equity!$N:$N,MATCH($B$2&"#"&22,Equity!$P:$P,0)),"")
A38: =IFERROR(INDEX(Equity!$B:$B,MATCH($B$2&"#"&23,Equity!$P:$P,0)),"") | B38: =IFERROR(INDEX(Equity!$C:$C,MATCH($B$2&"#"&23,Equity!$P:$P,0)),"") | C38: =IFERROR(INDEX(Equity!$D:$D,MATCH($B$2&"#"&23,Equity!$P:$P,0)),"") | D38: =IFERROR(INDEX(Equity!$E:$E,MATCH($B$2&"#"&23,Equity!$P:$P,0)),"") | E38: =IFERROR(INDEX(Equity!$I:$I,MATCH($B$2&"#"&23,Equity!$P:$P,0)),"") | F38: =IFERROR(INDEX(Equity!$K:$K,MATCH($B$2&"#"&23,Equity!$P:$P,0)),"") | G38: =IFERROR(INDEX(Equity!$N:$N,MATCH($B$2&"#"&23,Equity!$P:$P,0)),"")
A39: =IFERROR(INDEX(Equity!$B:$B,MATCH($B$2&"#"&24,Equity!$P:$P,0)),"") | B39: =IFERROR(INDEX(Equity!$C:$C,MATCH($B$2&"#"&24,Equity!$P:$P,0)),"") | C39: =IFERROR(INDEX(Equity!$D:$D,MATCH($B$2&"#"&24,Equity!$P:$P,0)),"") | D39: =IFERROR(INDEX(Equity!$E:$E,MATCH($B$2&"#"&24,Equity!$P:$P,0)),"") | E39: =IFERROR(INDEX(Equity!$I:$I,MATCH($B$2&"#"&24,Equity!$P:$P,0)),"") | F39: =IFERROR(INDEX(Equity!$K:$K,MATCH($B$2&"#"&24,Equity!$P:$P,0)),"") | G39: =IFERROR(INDEX(Equity!$N:$N,MATCH($B$2&"#"&24,Equity!$P:$P,0)),"")
A40: =IFERROR(INDEX(Equity!$B:$B,MATCH($B$2&"#"&25,Equity!$P:$P,0)),"") | B40: =IFERROR(INDEX(Equity!$C:$C,MATCH($B$2&"#"&25,Equity!$P:$P,0)),"") | C40: =IFERROR(INDEX(Equity!$D:$D,MATCH($B$2&"#"&25,Equity!$P:$P,0)),"") | D40: =IFERROR(INDEX(Equity!$E:$E,MATCH($B$2&"#"&25,Equity!$P:$P,0)),"") | E40: =IFERROR(INDEX(Equity!$I:$I,MATCH($B$2&"#"&25,Equity!$P:$P,0)),"") | F40: =IFERROR(INDEX(Equity!$K:$K,MATCH($B$2&"#"&25,Equity!$P:$P,0)),"") | G40: =IFERROR(INDEX(Equity!$N:$N,MATCH($B$2&"#"&25,Equity!$P:$P,0)),"")
A41: =IFERROR(INDEX(Equity!$B:$B,MATCH($B$2&"#"&26,Equity!$P:$P,0)),"") | B41: =IFERROR(INDEX(Equity!$C:$C,MATCH($B$2&"#"&26,Equity!$P:$P,0)),"") | C41: =IFERROR(INDEX(Equity!$D:$D,MATCH($B$2&"#"&26,Equity!$P:$P,0)),"") | D41: =IFERROR(INDEX(Equity!$E:$E,MATCH($B$2&"#"&26,Equity!$P:$P,0)),"") | E41: =IFERROR(INDEX(Equity!$I:$I,MATCH($B$2&"#"&26,Equity!$P:$P,0)),"") | F41: =IFERROR(INDEX(Equity!$K:$K,MATCH($B$2&"#"&26,Equity!$P:$P,0)),"") | G41: =IFERROR(INDEX(Equity!$N:$N,MATCH($B$2&"#"&26,Equity!$P:$P,0)),"")
A42: =IFERROR(INDEX(Equity!$B:$B,MATCH($B$2&"#"&27,Equity!$P:$P,0)),"") | B42: =IFERROR(INDEX(Equity!$C:$C,MATCH($B$2&"#"&27,Equity!$P:$P,0)),"") | C42: =IFERROR(INDEX(Equity!$D:$D,MATCH($B$2&"#"&27,Equity!$P:$P,0)),"") | D42: =IFERROR(INDEX(Equity!$E:$E,MATCH($B$2&"#"&27,Equity!$P:$P,0)),"") | E42: =IFERROR(INDEX(Equity!$I:$I,MATCH($B$2&"#"&27,Equity!$P:$P,0)),"") | F42: =IFERROR(INDEX(Equity!$K:$K,MATCH($B$2&"#"&27,Equity!$P:$P,0)),"") | G42: =IFERROR(INDEX(Equity!$N:$N,MATCH($B$2&"#"&27,Equity!$P:$P,0)),"")
A43: =IFERROR(INDEX(Equity!$B:$B,MATCH($B$2&"#"&28,Equity!$P:$P,0)),"") | B43: =IFERROR(INDEX(Equity!$C:$C,MATCH($B$2&"#"&28,Equity!$P:$P,0)),"") | C43: =IFERROR(INDEX(Equity!$D:$D,MATCH($B$2&"#"&28,Equity!$P:$P,0)),"") | D43: =IFERROR(INDEX(Equity!$E:$E,MATCH($B$2&"#"&28,Equity!$P:$P,0)),"") | E43: =IFERROR(INDEX(Equity!$I:$I,MATCH($B$2&"#"&28,Equity!$P:$P,0)),"") | F43: =IFERROR(INDEX(Equity!$K:$K,MATCH($B$2&"#"&28,Equity!$P:$P,0)),"") | G43: =IFERROR(INDEX(Equity!$N:$N,MATCH($B$2&"#"&28,Equity!$P:$P,0)),"")
...

Sheet Priya
A1: Priya — PORTFOLIO
A2: Owner | B2: Priya
A3: Net worth | B3: =B11 -> 1254684
A5: Asset class | B5: Value | C5: # holdings
A6: Equity | B6: =SUMIFS(Equity!$I:$I,Equity!$A:$A,$B$2) -> 222950 | C6: =COUNTIF(Equity!$A:$A,$B$2) -> 3
A7: Mutual Funds | B7: =SUMIFS(MutualFunds!$I:$I,MutualFunds!$A:$A,$B$2) -> 171733.97 | C7: =COUNTIF(MutualFunds!$A:$A,$B$2) -> 1
A8: Fixed Deposits | B8: =SUMIFS(FixedDeposits!$I:$I,FixedDeposits!$A:$A,$B$2) -> 0 | C8: =COUNTIF(FixedDeposits!$A:$A,$B$2) -> 0
A9: PPF | B9: =SUMIFS(PPF!$D:$D,PPF!$A:$A,$B$2) -> 860000 | C9: =COUNTIF(PPF!$A:$A,$B$2) -> 1
A10: Bonds | B10: =SUMIFS(Bonds!$K:$K,Bonds!$A:$A,$B$2) -> 0 | C10: =COUNTIF(Bonds!$A:$A,$B$2) -> 0
A11: Total | B11: =SUM(B6:B10) -> 1254684 | C11: =SUM(C6:C10) -> 5
A14: EQUITY
A15: ISIN | B15: Scrip | C15: Qty | D15: Avg cost | E15: Cur. val | F15: Net chg. | G15: XIRR
A16: =IFERROR(INDEX(Equity!$B:$B,MATCH($B$2&"#"&1,Equity!$P:$P,0)),"") -> INE154A01025 | B16: =IFERROR(INDEX(Equity!$C:$C,MATCH($B$2&"#"&1,Equity!$P:$P,0)),"") -> ITC LIMITED EQ | C16: =IFERROR(INDEX(Equity!$D:$D,MATCH($B$2&"#"&1,Equity!$P:$P,0)),"") -> 200 | D16: =IFERROR(INDEX(Equity!$E:$E,MATCH($B$2&"#"&1,Equity!$P:$P,0)),"") -> 282.6 | E16: =IFERROR(INDEX(Equity!$I:$I,MATCH($B$2&"#"&1,Equity!$P:$P,0)),"") -> 87000 | F16: =IFERROR(INDEX(Equity!$K:$K,MATCH($B$2&"#"&1,Equity!$P:$P,0)),"") -> 30480 | G16: =IFERROR(INDEX(Equity!$N:$N,MATCH($B$2&"#"&1,Equity!$P:$P,0)),"") -> 0.05233771
A17: =IFERROR(INDEX(Equity!$B:$B,MATCH($B$2&"#"&2,Equity!$P:$P,0)),"") -> INE090A01021 | B17: =IFERROR(INDEX(Equity!$C:$C,MATCH($B$2&"#"&2,Equity!$P:$P,0)),"") -> ICICI BANK LIMITED EQ | C17: =IFERROR(INDEX(Equity!$D:$D,MATCH($B$2&"#"&2,Equity!$P:$P,0)),"") -> 80 | D17: =IFERROR(INDEX(Equity!$E:$E,MATCH($B$2&"#"&2,Equity!$P:$P,0)),"") -> 365 | E17: =IFERROR(INDEX(Equity!$I:$I,MATCH($B$2&"#"&2,Equity!$P:$P,0)),"") -> 99200 | F17: =IFERROR(INDEX(Equity!$K:$K,MATCH($B$2&"#"&2,Equity!$P:$P,0)),"") -> 70000 | G17: =IFERROR(INDEX(Equity!$N:$N,MATCH($B$2&"#"&2,Equity!$P:$P,0)),"") -> 0.15563274
A18: =IFERROR(INDEX(Equity!$B:$B,MATCH($B$2&"#"&3,Equity!$P:$P,0)),"") -> INE075A01022 | B18: =IFERROR(INDEX(Equity!$C:$C,MATCH($B$2&"#"&3,Equity!$P:$P,0)),"") -> WIPRO LIMITED EQ | C18: =IFERROR(INDEX(Equity!$D:$D,MATCH($B$2&"#"&3,Equity!$P:$P,0)),"") -> 150 | D18: =IFERROR(INDEX(Equity!$E:$E,MATCH($B$2&"#"&3,Equity!$P:$P,0)),"") -> 317 | E18: =IFERROR(INDEX(Equity!$I:$I,MATCH($B$2&"#"&3,Equity!$P:$P,0)),"") -> 36750 | F18: =IFERROR(INDEX(Equity!$K:$K,MATCH($B$2&"#"&3,Equity!$P:$P,0)),"") -> -10800 | G18: =IFERROR(INDEX(Equity!$N:$N,MATCH($B$2&"#"&3,Equity!$P:$P,0)),"") -> -0.030013449
A19: =IFERROR(INDEX(Equity!$B:$B,MATCH($B$2&"#"&4,Equity!$P:$P,0)),"") | B19: =IFERROR(INDEX(Equity!$C:$C,MATCH($B$2&"#"&4,Equity!$P:$P,0)),"") | C19: =IFERROR(INDEX(Equity!$D:$D,MATCH($B$2&"#"&4,Equity!$P:$P,0)),"") | D19: =IFERROR(INDEX(Equity!$E:$E,MATCH($B$2&"#"&4,Equity!$P:$P,0)),"") | E19: =IFERROR(INDEX(Equity!$I:$I,MATCH($B$2&"#"&4,Equity!$P:$P,0)),"") | F19: =IFERROR(INDEX(Equity!$K:$K,MATCH($B$2&"#"&4,Equity!$P:$P,0)),"") | G19: =IFERROR(INDEX(Equity!$N:$N,MATCH($B$2&"#"&4,Equity!$P:$P,0)),"")
A20: =IFERROR(INDEX(Equity!$B:$B,MATCH($B$2&"#"&5,Equity!$P:$P,0)),"") | B20: =IFERROR(INDEX(Equity!$C:$C,MATCH($B$2&"#"&5,Equity!$P:$P,0)),"") | C20: =IFERROR(INDEX(Equity!$D:$D,MATCH($B$2&"#"&5,Equity!$P:$P,0)),"") | D20: =IFERROR(INDEX(Equity!$E:$E,MATCH($B$2&"#"&5,Equity!$P:$P,0)),"") | E20: =IFERROR(INDEX(Equity!$I:$I,MATCH($B$2&"#"&5,Equity!$P:$P,0)),"") | F20: =IFERROR(INDEX(Equity!$K:$K,MATCH($B$2&"#"&5,Equity!$P:$P,0)),"") | G20: =IFERROR(INDEX(Equity!$N:$N,MATCH($B$2&"#"&5,Equity!$P:$P,0)),"")
A21: =IFERROR(INDEX(Equity!$B:$B,MATCH($B$2&"#"&6,Equity!$P:$P,0)),"") | B21: =IFERROR(INDEX(Equity!$C:$C,MATCH($B$2&"#"&6,Equity!$P:$P,0)),"") | C21: =IFERROR(INDEX(Equity!$D:$D,MATCH($B$2&"#"&6,Equity!$P:$P,0)),"") | D21: =IFERROR(INDEX(Equity!$E:$E,MATCH($B$2&"#"&6,Equity!$P:$P,0)),"") | E21: =IFERROR(INDEX(Equity!$I:$I,MATCH($B$2&"#"&6,Equity!$P:$P,0)),"") | F21: =IFERROR(INDEX(Equity!$K:$K,MATCH($B$2&"#"&6,Equity!$P:$P,0)),"") | G21: =IFERROR(INDEX(Equity!$N:$N,MATCH($B$2&"#"&6,Equity!$P:$P,0)),"")
A22: =IFERROR(INDEX(Equity!$B:$B,MATCH($B$2&"#"&7,Equity!$P:$P,0)),"") | B22: =IFERROR(INDEX(Equity!$C:$C,MATCH($B$2&"#"&7,Equity!$P:$P,0)),"") | C22: =IFERROR(INDEX(Equity!$D:$D,MATCH($B$2&"#"&7,Equity!$P:$P,0)),"") | D22: =IFERROR(INDEX(Equity!$E:$E,MATCH($B$2&"#"&7,Equity!$P:$P,0)),"") | E22: =IFERROR(INDEX(Equity!$I:$I,MATCH($B$2&"#"&7,Equity!$P:$P,0)),"") | F22: =IFERROR(INDEX(Equity!$K:$K,MATCH($B$2&"#"&7,Equity!$P:$P,0)),"") | G22: =IFERROR(INDEX(Equity!$N:$N,MATCH($B$2&"#"&7,Equity!$P:$P,0)),"")
A23: =IFERROR(INDEX(Equity!$B:$B,MATCH($B$2&"#"&8,Equity!$P:$P,0)),"") | B23: =IFERROR(INDEX(Equity!$C:$C,MATCH($B$2&"#"&8,Equity!$P:$P,0)),"") | C23: =IFERROR(INDEX(Equity!$D:$D,MATCH($B$2&"#"&8,Equity!$P:$P,0)),"") | D23: =IFERROR(INDEX(Equity!$E:$E,MATCH($B$2&"#"&8,Equity!$P:$P,0)),"") | E23: =IFERROR(INDEX(Equity!$I:$I,MATCH($B$2&"#"&8,Equity!$P:$P,0)),"") | F23: =IFERROR(INDEX(Equity!$K:$K,MATCH($B$2&"#"&8,Equity!$P:$P,0)),"") | G23: =IFERROR(INDEX(Equity!$N:$N,MATCH($B$2&"#"&8,Equity!$P:$P,0)),"")
A24: =IFERROR(INDEX(Equity!$B:$B,MATCH($B$2&"#"&9,Equity!$P:$P,0)),"") | B24: =IFERROR(INDEX(Equity!$C:$C,MATCH($B$2&"#"&9,Equity!$P:$P,0)),"") | C24: =IFERROR(INDEX(Equity!$D:$D,MATCH($B$2&"#"&9,Equity!$P:$P,0)),"") | D24: =IFERROR(INDEX(Equity!$E:$E,MATCH($B$2&"#"&9,Equity!$P:$P,0)),"") | E24: =IFERROR(INDEX(Equity!$I:$I,MATCH($B$2&"#"&9,Equity!$P:$P,0)),"") | F24: =IFERROR(INDEX(Equity!$K:$K,MATCH($B$2&"#"&9,Equity!$P:$P,0)),"") | G24: =IFERROR(INDEX(Equity!$N:$N,MATCH($B$2&"#"&9,Equity!$P:$P,0)),"")
A25: =IFERROR(INDEX(Equity!$B:$B,MATCH($B$2&"#"&10,Equity!$P:$P,0)),"") | B25: =IFERROR(INDEX(Equity!$C:$C,MATCH($B$2&"#"&10,Equity!$P:$P,0)),"") | C25: =IFERROR(INDEX(Equity!$D:$D,MATCH($B$2&"#"&10,Equity!$P:$P,0)),"") | D25: =IFERROR(INDEX(Equity!$E:$E,MATCH($B$2&"#"&10,Equity!$P:$P,0)),"") | E25: =IFERROR(INDEX(Equity!$I:$I,MATCH($B$2&"#"&10,Equity!$P:$P,0)),"") | F25: =IFERROR(INDEX(Equity!$K:$K,MATCH($B$2&"#"&10,Equity!$P:$P,0)),"") | G25: =IFERROR(INDEX(Equity!$N:$N,MATCH($B$2&"#"&10,Equity!$P:$P,0)),"")
A26: =IFERROR(INDEX(Equity!$B:$B,MATCH($B$2&"#"&11,Equity!$P:$P,0)),"") | B26: =IFERROR(INDEX(Equity!$C:$C,MATCH($B$2&"#"&11,Equity!$P:$P,0)),"") | C26: =IFERROR(INDEX(Equity!$D:$D,MATCH($B$2&"#"&11,Equity!$P:$P,0)),"") | D26: =IFERROR(INDEX(Equity!$E:$E,MATCH($B$2&"#"&11,Equity!$P:$P,0)),"") | E26: =IFERROR(INDEX(Equity!$I:$I,MATCH($B$2&"#"&11,Equity!$P:$P,0)),"") | F26: =IFERROR(INDEX(Equity!$K:$K,MATCH($B$2&"#"&11,Equity!$P:$P,0)),"") | G26: =IFERROR(INDEX(Equity!$N:$N,MATCH($B$2&"#"&11,Equity!$P:$P,0)),"")
A27: =IFERROR(INDEX(Equity!$B:$B,MATCH($B$2&"#"&12,Equity!$P:$P,0)),"") | B27: =IFERROR(INDEX(Equity!$C:$C,MATCH($B$2&"#"&12,Equity!$P:$P,0)),"") | C27: =IFERROR(INDEX(Equity!$D:$D,MATCH($B$2&"#"&12,Equity!$P:$P,0)),"") | D27: =IFERROR(INDEX(Equity!$E:$E,MATCH($B$2&"#"&12,Equity!$P:$P,0)),"") | E27: =IFERROR(INDEX(Equity!$I:$I,MATCH($B$2&"#"&12,Equity!$P:$P,0)),"") | F27: =IFERROR(INDEX(Equity!$K:$K,MATCH($B$2&"#"&12,Equity!$P:$P,0)),"") | G27: =IFERROR(INDEX(Equity!$N:$N,MATCH($B$2&"#"&12,Equity!$P:$P,0)),"")
A28: =IFERROR(INDEX(Equity!$B:$B,MATCH($B$2&"#"&13,Equity!$P:$P,0)),"") | B28: =IFERROR(INDEX(Equity!$C:$C,MATCH($B$2&"#"&13,Equity!$P:$P,0)),"") | C28: =IFERROR(INDEX(Equity!$D:$D,MATCH($B$2&"#"&13,Equity!$P:$P,0)),"") | D28: =IFERROR(INDEX(Equity!$E:$E,MATCH($B$2&"#"&13,Equity!$P:$P,0)),"") | E28: =IFERROR(INDEX(Equity!$I:$I,MATCH($B$2&"#"&13,Equity!$P:$P,0)),"") | F28: =IFERROR(INDEX(Equity!$K:$K,MATCH($B$2&"#"&13,Equity!$P:$P,0)),"") | G28: =IFERROR(INDEX(Equity!$N:$N,MATCH($B$2&"#"&13,Equity!$P:$P,0)),"")
A29: =IFERROR(INDEX(Equity!$B:$B,MATCH($B$2&"#"&14,Equity!$P:$P,0)),"") | B29: =IFERROR(INDEX(Equity!$C:$C,MATCH($B$2&"#"&14,Equity!$P:$P,0)),"") | C29: =IFERROR(INDEX(Equity!$D:$D,MATCH($B$2&"#"&14,Equity!$P:$P,0)),"") | D29: =IFERROR(INDEX(Equity!$E:$E,MATCH($B$2&"#"&14,Equity!$P:$P,0)),"") | E29: =IFERROR(INDEX(Equity!$I:$I,MATCH($B$2&"#"&14,Equity!$P:$P,0)),"") | F29: =IFERROR(INDEX(Equity!$K:$K,MATCH($B$2&"#"&14,Equity!$P:$P,0)),"") | G29: =IFERROR(INDEX(Equity!$N:$N,MATCH($B$2&"#"&14,Equity!$P:$P,0)),"")
A30: =IFERROR(INDEX(Equity!$B:$B,MATCH($B$2&"#"&15,Equity!$P:$P,0)),"") | B30: =IFERROR(INDEX(Equity!$C:$C,MATCH($B$2&"#"&15,Equity!$P:$P,0)),"") | C30: =IFERROR(INDEX(Equity!$D:$D,MATCH($B$2&"#"&15,Equity!$P:$P,0)),"") | D30: =IFERROR(INDEX(Equity!$E:$E,MATCH($B$2&"#"&15,Equity!$P:$P,0)),"") | E30: =IFERROR(INDEX(Equity!$I:$I,MATCH($B$2&"#"&15,Equity!$P:$P,0)),"") | F30: =IFERROR(INDEX(Equity!$K:$K,MATCH($B$2&"#"&15,Equity!$P:$P,0)),"") | G30: =IFERROR(INDEX(Equity!$N:$N,MATCH($B$2&"#"&15,Equity!$P:$P,0)),"")
A31: =IFERROR(INDEX(Equity!$B:$B,MATCH($B$2&"#"&16,Equity!$P:$P,0)),"") | B31: =IFERROR(INDEX(Equity!$C:$C,MATCH($B$2&"#"&16,Equity!$P:$P,0)),"") | C31: =IFERROR(INDEX(Equity!$D:$D,MATCH($B$2&"#"&16,Equity!$P:$P,0)),"") | D31: =IFERROR(INDEX(Equity!$E:$E,MATCH($B$2&"#"&16,Equity!$P:$P,0)),"") | E31: =IFERROR(INDEX(Equity!$I:$I,MATCH($B$2&"#"&16,Equity!$P:$P,0)),"") | F31: =IFERROR(INDEX(Equity!$K:$K,MATCH($B$2&"#"&16,Equity!$P:$P,0)),"") | G31: =IFERROR(INDEX(Equity!$N:$N,MATCH($B$2&"#"&16,Equity!$P:$P,0)),"")
A32: =IFERROR(INDEX(Equity!$B:$B,MATCH($B$2&"#"&17,Equity!$P:$P,0)),"") | B32: =IFERROR(INDEX(Equity!$C:$C,MATCH($B$2&"#"&17,Equity!$P:$P,0)),"") | C32: =IFERROR(INDEX(Equity!$D:$D,MATCH($B$2&"#"&17,Equity!$P:$P,0)),"") | D32: =IFERROR(INDEX(Equity!$E:$E,MATCH($B$2&"#"&17,Equity!$P:$P,0)),"") | E32: =IFERROR(INDEX(Equity!$I:$I,MATCH($B$2&"#"&17,Equity!$P:$P,0)),"") | F32: =IFERROR(INDEX(Equity!$K:$K,MATCH($B$2&"#"&17,Equity!$P:$P,0)),"") | G32: =IFERROR(INDEX(Equity!$N:$N,MATCH($B$2&"#"&17,Equity!$P:$P,0)),"")
A33: =IFERROR(INDEX(Equity!$B:$B,MATCH($B$2&"#"&18,Equity!$P:$P,0)),"") | B33: =IFERROR(INDEX(Equity!$C:$C,MATCH($B$2&"#"&18,Equity!$P:$P,0)),"") | C33: =IFERROR(INDEX(Equity!$D:$D,MATCH($B$2&"#"&18,Equity!$P:$P,0)),"") | D33: =IFERROR(INDEX(Equity!$E:$E,MATCH($B$2&"#"&18,Equity!$P:$P,0)),"") | E33: =IFERROR(INDEX(Equity!$I:$I,MATCH($B$2&"#"&18,Equity!$P:$P,0)),"") | F33: =IFERROR(INDEX(Equity!$K:$K,MATCH($B$2&"#"&18,Equity!$P:$P,0)),"") | G33: =IFERROR(INDEX(Equity!$N:$N,MATCH($B$2&"#"&18,Equity!$P:$P,0)),"")
A34: =IFERROR(INDEX(Equity!$B:$B,MATCH($B$2&"#"&19,Equity!$P:$P,0)),"") | B34: =IFERROR(INDEX(Equity!$C:$C,MATCH($B$2&"#"&19,Equity!$P:$P,0)),"") | C34: =IFERROR(INDEX(Equity!$D:$D,MATCH($B$2&"#"&19,Equity!$P:$P,0)),"") | D34: =IFERROR(INDEX(Equity!$E:$E,MATCH($B$2&"#"&19,Equity!$P:$P,0)),"") | E34: =IFERROR(INDEX(Equity!$I:$I,MATCH($B$2&"#"&19,Equity!$P:$P,0)),"") | F34: =IFERROR(INDEX(Equity!$K:$K,MATCH($B$2&"#"&19,Equity!$P:$P,0)),"") | G34: =IFERROR(INDEX(Equity!$N:$N,MATCH($B$2&"#"&19,Equity!$P:$P,0)),"")
A35: =IFERROR(INDEX(Equity!$B:$B,MATCH($B$2&"#"&20,Equity!$P:$P,0)),"") | B35: =IFERROR(INDEX(Equity!$C:$C,MATCH($B$2&"#"&20,Equity!$P:$P,0)),"") | C35: =IFERROR(INDEX(Equity!$D:$D,MATCH($B$2&"#"&20,Equity!$P:$P,0)),"") | D35: =IFERROR(INDEX(Equity!$E:$E,MATCH($B$2&"#"&20,Equity!$P:$P,0)),"") | E35: =IFERROR(INDEX(Equity!$I:$I,MATCH($B$2&"#"&20,Equity!$P:$P,0)),"") | F35: =IFERROR(INDEX(Equity!$K:$K,MATCH($B$2&"#"&20,Equity!$P:$P,0)),"") | G35: =IFERROR(INDEX(Equity!$N:$N,MATCH($B$2&"#"&20,Equity!$P:$P,0)),"")
A36: =IFERROR(INDEX(Equity!$B:$B,MATCH($B$2&"#"&21,Equity!$P:$P,0)),"") | B36: =IFERROR(INDEX(Equity!$C:$C,MATCH($B$2&"#"&21,Equity!$P:$P,0)),"") | C36: =IFERROR(INDEX(Equity!$D:$D,MATCH($B$2&"#"&21,Equity!$P:$P,0)),"") | D36: =IFERROR(INDEX(Equity!$E:$E,MATCH($B$2&"#"&21,Equity!$P:$P,0)),"") | E36: =IFERROR(INDEX(Equity!$I:$I,MATCH($B$2&"#"&21,Equity!$P:$P,0)),"") | F36: =IFERROR(INDEX(Equity!$K:$K,MATCH($B$2&"#"&21,Equity!$P:$P,0)),"") | G36: =IFERROR(INDEX(Equity!$N:$N,MATCH($B$2&"#"&21,Equity!$P:$P,0)),"")
A37: =IFERROR(INDEX(Equity!$B:$B,MATCH($B$2&"#"&22,Equity!$P:$P,0)),"") | B37: =IFERROR(INDEX(Equity!$C:$C,MATCH($B$2&"#"&22,Equity!$P:$P,0)),"") | C37: =IFERROR(INDEX(Equity!$D:$D,MATCH($B$2&"#"&22,Equity!$P:$P,0)),"") | D37: =IFERROR(INDEX(Equity!$E:$E,MATCH($B$2&"#"&22,Equity!$P:$P,0)),"") | E37: =IFERROR(INDEX(Equity!$I:$I,MATCH($B$2&"#"&22,Equity!$P:$P,0)),"") | F37: =IFERROR(INDEX(Equity!$K:$K,MATCH($B$2&"#"&22,Equity!$P:$P,0)),"") | G37: =IFERROR(INDEX(Equity!$N:$N,MATCH($B$2&"#"&22,Equity!$P:$P,0)),"")
A38: =IFERROR(INDEX(Equity!$B:$B,MATCH($B$2&"#"&23,Equity!$P:$P,0)),"") | B38: =IFERROR(INDEX(Equity!$C:$C,MATCH($B$2&"#"&23,Equity!$P:$P,0)),"") | C38: =IFERROR(INDEX(Equity!$D:$D,MATCH($B$2&"#"&23,Equity!$P:$P,0)),"") | D38: =IFERROR(INDEX(Equity!$E:$E,MATCH($B$2&"#"&23,Equity!$P:$P,0)),"") | E38: =IFERROR(INDEX(Equity!$I:$I,MATCH($B$2&"#"&23,Equity!$P:$P,0)),"") | F38: =IFERROR(INDEX(Equity!$K:$K,MATCH($B$2&"#"&23,Equity!$P:$P,0)),"") | G38: =IFERROR(INDEX(Equity!$N:$N,MATCH($B$2&"#"&23,Equity!$P:$P,0)),"")
A39: =IFERROR(INDEX(Equity!$B:$B,MATCH($B$2&"#"&24,Equity!$P:$P,0)),"") | B39: =IFERROR(INDEX(Equity!$C:$C,MATCH($B$2&"#"&24,Equity!$P:$P,0)),"") | C39: =IFERROR(INDEX(Equity!$D:$D,MATCH($B$2&"#"&24,Equity!$P:$P,0)),"") | D39: =IFERROR(INDEX(Equity!$E:$E,MATCH($B$2&"#"&24,Equity!$P:$P,0)),"") | E39: =IFERROR(INDEX(Equity!$I:$I,MATCH($B$2&"#"&24,Equity!$P:$P,0)),"") | F39: =IFERROR(INDEX(Equity!$K:$K,MATCH($B$2&"#"&24,Equity!$P:$P,0)),"") | G39: =IFERROR(INDEX(Equity!$N:$N,MATCH($B$2&"#"&24,Equity!$P:$P,0)),"")
A40: =IFERROR(INDEX(Equity!$B:$B,MATCH($B$2&"#"&25,Equity!$P:$P,0)),"") | B40: =IFERROR(INDEX(Equity!$C:$C,MATCH($B$2&"#"&25,Equity!$P:$P,0)),"") | C40: =IFERROR(INDEX(Equity!$D:$D,MATCH($B$2&"#"&25,Equity!$P:$P,0)),"") | D40: =IFERROR(INDEX(Equity!$E:$E,MATCH($B$2&"#"&25,Equity!$P:$P,0)),"") | E40: =IFERROR(INDEX(Equity!$I:$I,MATCH($B$2&"#"&25,Equity!$P:$P,0)),"") | F40: =IFERROR(INDEX(Equity!$K:$K,MATCH($B$2&"#"&25,Equity!$P:$P,0)),"") | G40: =IFERROR(INDEX(Equity!$N:$N,MATCH($B$2&"#"&25,Equity!$P:$P,0)),"")
A41: =IFERROR(INDEX(Equity!$B:$B,MATCH($B$2&"#"&26,Equity!$P:$P,0)),"") | B41: =IFERROR(INDEX(Equity!$C:$C,MATCH($B$2&"#"&26,Equity!$P:$P,0)),"") | C41: =IFERROR(INDEX(Equity!$D:$D,MATCH($B$2&"#"&26,Equity!$P:$P,0)),"") | D41: =IFERROR(INDEX(Equity!$E:$E,MATCH($B$2&"#"&26,Equity!$P:$P,0)),"") | E41: =IFERROR(INDEX(Equity!$I:$I,MATCH($B$2&"#"&26,Equity!$P:$P,0)),"") | F41: =IFERROR(INDEX(Equity!$K:$K,MATCH($B$2&"#"&26,Equity!$P:$P,0)),"") | G41: =IFERROR(INDEX(Equity!$N:$N,MATCH($B$2&"#"&26,Equity!$P:$P,0)),"")
A42: =IFERROR(INDEX(Equity!$B:$B,MATCH($B$2&"#"&27,Equity!$P:$P,0)),"") | B42: =IFERROR(INDEX(Equity!$C:$C,MATCH($B$2&"#"&27,Equity!$P:$P,0)),"") | C42: =IFERROR(INDEX(Equity!$D:$D,MATCH($B$2&"#"&27,Equity!$P:$P,0)),"") | D42: =IFERROR(INDEX(Equity!$E:$E,MATCH($B$2&"#"&27,Equity!$P:$P,0)),"") | E42: =IFERROR(INDEX(Equity!$I:$I,MATCH($B$2&"#"&27,Equity!$P:$P,0)),"") | F42: =IFERROR(INDEX(Equity!$K:$K,MATCH($B$2&"#"&27,Equity!$P:$P,0)),"") | G42: =IFERROR(INDEX(Equity!$N:$N,MATCH($B$2&"#"&27,Equity!$P:$P,0)),"")
A43: =IFERROR(INDEX(Equity!$B:$B,MATCH($B$2&"#"&28,Equity!$P:$P,0)),"") | B43: =IFERROR(INDEX(Equity!$C:$C,MATCH($B$2&"#"&28,Equity!$P:$P,0)),"") | C43: =IFERROR(INDEX(Equity!$D:$D,MATCH($B$2&"#"&28,Equity!$P:$P,0)),"") | D43: =IFERROR(INDEX(Equity!$E:$E,MATCH($B$2&"#"&28,Equity!$P:$P,0)),"") | E43: =IFERROR(INDEX(Equity!$I:$I,MATCH($B$2&"#"&28,Equity!$P:$P,0)),"") | F43: =IFERROR(INDEX(Equity!$K:$K,MATCH($B$2&"#"&28,Equity!$P:$P,0)),"") | G43: =IFERROR(INDEX(Equity!$N:$N,MATCH($B$2&"#"&28,Equity!$P:$P,0)),"")
...

Sheet Rahul
A1: Rahul — PORTFOLIO
A2: Owner | B2: Rahul
A3: Net worth | B3: =B11 -> 643218.19
A5: Asset class | B5: Value | C5: # holdings
A6: Equity | B6: =SUMIFS(Equity!$I:$I,Equity!$A:$A,$B$2) -> 260600 | C6: =COUNTIF(Equity!$A:$A,$B$2) -> 3
A7: Mutual Funds | B7: =SUMIFS(MutualFunds!$I:$I,MutualFunds!$A:$A,$B$2) -> 0 | C7: =COUNTIF(MutualFunds!$A:$A,$B$2) -> 0
A8: Fixed Deposits | B8: =SUMIFS(FixedDeposits!$I:$I,FixedDeposits!$A:$A,$B$2) -> 331868.19 | C8: =COUNTIF(FixedDeposits!$A:$A,$B$2) -> 1
A9: PPF | B9: =SUMIFS(PPF!$D:$D,PPF!$A:$A,$B$2) -> 0 | C9: =COUNTIF(PPF!$A:$A,$B$2) -> 0
A10: Bonds | B10: =SUMIFS(Bonds!$K:$K,Bonds!$A:$A,$B$2) -> 50750 | C10: =COUNTIF(Bonds!$A:$A,$B$2) -> 1
A11: Total | B11: =SUM(B6:B10) -> 643218.19 | C11: =SUM(C6:C10) -> 5
A14: EQUITY
A15: ISIN | B15: Scrip | C15: Qty | D15: Avg cost | E15: Cur. val | F15: Net chg. | G15: XIRR
A16: =IFERROR(INDEX(Equity!$B:$B,MATCH($B$2&"#"&1,Equity!$P:$P,0)),"") -> INE018A01030 | B16: =IFERROR(INDEX(Equity!$C:$C,MATCH($B$2&"#"&1,Equity!$P:$P,0)),"") -> LARSEN & TOUBRO LIMITED EQ | C16: =IFERROR(INDEX(Equity!$D:$D,MATCH($B$2&"#"&1,Equity!$P:$P,0)),"") -> 25 | D16: =IFERROR(INDEX(Equity!$E:$E,MATCH($B$2&"#"&1,Equity!$P:$P,0)),"") -> 1470 | E16: =IFERROR(INDEX(Equity!$I:$I,MATCH($B$2&"#"&1,Equity!$P:$P,0)),"") -> 90500 | F16: =IFERROR(INDEX(Equity!$K:$K,MATCH($B$2&"#"&1,Equity!$P:$P,0)),"") -> 53750 | G16: =IFERROR(INDEX(Equity!$N:$N,MATCH($B$2&"#"&1,Equity!$P:$P,0)),"") -> 0.11248003
A17: =IFERROR(INDEX(Equity!$B:$B,MATCH($B$2&"#"&2,Equity!$P:$P,0)),"") -> INE062A01020 | B17: =IFERROR(INDEX(Equity!$C:$C,MATCH($B$2&"#"&2,Equity!$P:$P,0)),"") -> STATE BANK OF INDIA EQ | C17: =IFERROR(INDEX(Equity!$D:$D,MATCH($B$2&"#"&2,Equity!$P:$P,0)),"") -> 120 | D17: =IFERROR(INDEX(Equity!$E:$E,MATCH($B$2&"#"&2,Equity!$P:$P,0)),"") -> 327 | E17: =IFERROR(INDEX(Equity!$I:$I,MATCH($B$2&"#"&2,Equity!$P:$P,0)),"") -> 97800 | F17: =IFERROR(INDEX(Equity!$K:$K,MATCH($B$2&"#"&2,Equity!$P:$P,0)),"") -> 58560 | G17: =IFERROR(INDEX(Equity!$N:$N,MATCH($B$2&"#"&2,Equity!$P:$P,0)),"") -> 0.11406226
A18: =IFERROR(INDEX(Equity!$B:$B,MATCH($B$2&"#"&3,Equity!$P:$P,0)),"") -> INE030A01027 | B18: =IFERROR(INDEX(Equity!$C:$C,MATCH($B$2&"#"&3,Equity!$P:$P,0)),"") -> HINDUSTAN UNILEVER LIMITED EQ | C18: =IFERROR(INDEX(Equity!$D:$D,MATCH($B$2&"#"&3,Equity!$P:$P,0)),"") -> 30 | D18: =IFERROR(INDEX(Equity!$E:$E,MATCH($B$2&"#"&3,Equity!$P:$P,0)),"") -> 1370 | E18: =IFERROR(INDEX(Equity!$I:$I,MATCH($B$2&"#"&3,Equity!$P:$P,0)),"") -> 72300 | F18: =IFERROR(INDEX(Equity!$K:$K,MATCH($B$2&"#"&3,Equity!$P:$P,0)),"") -> 31200 | G18: =IFERROR(INDEX(Equity!$N:$N,MATCH($B$2&"#"&3,Equity!$P:$P,0)),"") -> 0.069086159
A19: =IFERROR(INDEX(Equity!$B:$B,MATCH($B$2&"#"&4,Equity!$P:$P,0)),"") | B19: =IFERROR(INDEX(Equity!$C:$C,MATCH($B$2&"#"&4,Equity!$P:$P,0)),"") | C19: =IFERROR(INDEX(Equity!$D:$D,MATCH($B$2&"#"&4,Equity!$P:$P,0)),"") | D19: =IFERROR(INDEX(Equity!$E:$E,MATCH($B$2&"#"&4,Equity!$P:$P,0)),"") | E19: =IFERROR(INDEX(Equity!$I:$I,MATCH($B$2&"#"&4,Equity!$P:$P,0)),"") | F19: =IFERROR(INDEX(Equity!$K:$K,MATCH($B$2&"#"&4,Equity!$P:$P,0)),"") | G19: =IFERROR(INDEX(Equity!$N:$N,MATCH($B$2&"#"&4,Equity!$P:$P,0)),"")
A20: =IFERROR(INDEX(Equity!$B:$B,MATCH($B$2&"#"&5,Equity!$P:$P,0)),"") | B20: =IFERROR(INDEX(Equity!$C:$C,MATCH($B$2&"#"&5,Equity!$P:$P,0)),"") | C20: =IFERROR(INDEX(Equity!$D:$D,MATCH($B$2&"#"&5,Equity!$P:$P,0)),"") | D20: =IFERROR(INDEX(Equity!$E:$E,MATCH($B$2&"#"&5,Equity!$P:$P,0)),"") | E20: =IFERROR(INDEX(Equity!$I:$I,MATCH($B$2&"#"&5,Equity!$P:$P,0)),"") | F20: =IFERROR(INDEX(Equity!$K:$K,MATCH($B$2&"#"&5,Equity!$P:$P,0)),"") | G20: =IFERROR(INDEX(Equity!$N:$N,MATCH($B$2&"#"&5,Equity!$P:$P,0)),"")
A21: =IFERROR(INDEX(Equity!$B:$B,MATCH($B$2&"#"&6,Equity!$P:$P,0)),"") | B21: =IFERROR(INDEX(Equity!$C:$C,MATCH($B$2&"#"&6,Equity!$P:$P,0)),"") | C21: =IFERROR(INDEX(Equity!$D:$D,MATCH($B$2&"#"&6,Equity!$P:$P,0)),"") | D21: =IFERROR(INDEX(Equity!$E:$E,MATCH($B$2&"#"&6,Equity!$P:$P,0)),"") | E21: =IFERROR(INDEX(Equity!$I:$I,MATCH($B$2&"#"&6,Equity!$P:$P,0)),"") | F21: =IFERROR(INDEX(Equity!$K:$K,MATCH($B$2&"#"&6,Equity!$P:$P,0)),"") | G21: =IFERROR(INDEX(Equity!$N:$N,MATCH($B$2&"#"&6,Equity!$P:$P,0)),"")
A22: =IFERROR(INDEX(Equity!$B:$B,MATCH($B$2&"#"&7,Equity!$P:$P,0)),"") | B22: =IFERROR(INDEX(Equity!$C:$C,MATCH($B$2&"#"&7,Equity!$P:$P,0)),"") | C22: =IFERROR(INDEX(Equity!$D:$D,MATCH($B$2&"#"&7,Equity!$P:$P,0)),"") | D22: =IFERROR(INDEX(Equity!$E:$E,MATCH($B$2&"#"&7,Equity!$P:$P,0)),"") | E22: =IFERROR(INDEX(Equity!$I:$I,MATCH($B$2&"#"&7,Equity!$P:$P,0)),"") | F22: =IFERROR(INDEX(Equity!$K:$K,MATCH($B$2&"#"&7,Equity!$P:$P,0)),"") | G22: =IFERROR(INDEX(Equity!$N:$N,MATCH($B$2&"#"&7,Equity!$P:$P,0)),"")
A23: =IFERROR(INDEX(Equity!$B:$B,MATCH($B$2&"#"&8,Equity!$P:$P,0)),"") | B23: =IFERROR(INDEX(Equity!$C:$C,MATCH($B$2&"#"&8,Equity!$P:$P,0)),"") | C23: =IFERROR(INDEX(Equity!$D:$D,MATCH($B$2&"#"&8,Equity!$P:$P,0)),"") | D23: =IFERROR(INDEX(Equity!$E:$E,MATCH($B$2&"#"&8,Equity!$P:$P,0)),"") | E23: =IFERROR(INDEX(Equity!$I:$I,MATCH($B$2&"#"&8,Equity!$P:$P,0)),"") | F23: =IFERROR(INDEX(Equity!$K:$K,MATCH($B$2&"#"&8,Equity!$P:$P,0)),"") | G23: =IFERROR(INDEX(Equity!$N:$N,MATCH($B$2&"#"&8,Equity!$P:$P,0)),"")
A24: =IFERROR(INDEX(Equity!$B:$B,MATCH($B$2&"#"&9,Equity!$P:$P,0)),"") | B24: =IFERROR(INDEX(Equity!$C:$C,MATCH($B$2&"#"&9,Equity!$P:$P,0)),"") | C24: =IFERROR(INDEX(Equity!$D:$D,MATCH($B$2&"#"&9,Equity!$P:$P,0)),"") | D24: =IFERROR(INDEX(Equity!$E:$E,MATCH($B$2&"#"&9,Equity!$P:$P,0)),"") | E24: =IFERROR(INDEX(Equity!$I:$I,MATCH($B$2&"#"&9,Equity!$P:$P,0)),"") | F24: =IFERROR(INDEX(Equity!$K:$K,MATCH($B$2&"#"&9,Equity!$P:$P,0)),"") | G24: =IFERROR(INDEX(Equity!$N:$N,MATCH($B$2&"#"&9,Equity!$P:$P,0)),"")
A25: =IFERROR(INDEX(Equity!$B:$B,MATCH($B$2&"#"&10,Equity!$P:$P,0)),"") | B25: =IFERROR(INDEX(Equity!$C:$C,MATCH($B$2&"#"&10,Equity!$P:$P,0)),"") | C25: =IFERROR(INDEX(Equity!$D:$D,MATCH($B$2&"#"&10,Equity!$P:$P,0)),"") | D25: =IFERROR(INDEX(Equity!$E:$E,MATCH($B$2&"#"&10,Equity!$P:$P,0)),"") | E25: =IFERROR(INDEX(Equity!$I:$I,MATCH($B$2&"#"&10,Equity!$P:$P,0)),"") | F25: =IFERROR(INDEX(Equity!$K:$K,MATCH($B$2&"#"&10,Equity!$P:$P,0)),"") | G25: =IFERROR(INDEX(Equity!$N:$N,MATCH($B$2&"#"&10,Equity!$P:$P,0)),"")
A26: =IFERROR(INDEX(Equity!$B:$B,MATCH($B$2&"#"&11,Equity!$P:$P,0)),"") | B26: =IFERROR(INDEX(Equity!$C:$C,MATCH($B$2&"#"&11,Equity!$P:$P,0)),"") | C26: =IFERROR(INDEX(Equity!$D:$D,MATCH($B$2&"#"&11,Equity!$P:$P,0)),"") | D26: =IFERROR(INDEX(Equity!$E:$E,MATCH($B$2&"#"&11,Equity!$P:$P,0)),"") | E26: =IFERROR(INDEX(Equity!$I:$I,MATCH($B$2&"#"&11,Equity!$P:$P,0)),"") | F26: =IFERROR(INDEX(Equity!$K:$K,MATCH($B$2&"#"&11,Equity!$P:$P,0)),"") | G26: =IFERROR(INDEX(Equity!$N:$N,MATCH($B$2&"#"&11,Equity!$P:$P,0)),"")
A27: =IFERROR(INDEX(Equity!$B:$B,MATCH($B$2&"#"&12,Equity!$P:$P,0)),"") | B27: =IFERROR(INDEX(Equity!$C:$C,MATCH($B$2&"#"&12,Equity!$P:$P,0)),"") | C27: =IFERROR(INDEX(Equity!$D:$D,MATCH($B$2&"#"&12,Equity!$P:$P,0)),"") | D27: =IFERROR(INDEX(Equity!$E:$E,MATCH($B$2&"#"&12,Equity!$P:$P,0)),"") | E27: =IFERROR(INDEX(Equity!$I:$I,MATCH($B$2&"#"&12,Equity!$P:$P,0)),"") | F27: =IFERROR(INDEX(Equity!$K:$K,MATCH($B$2&"#"&12,Equity!$P:$P,0)),"") | G27: =IFERROR(INDEX(Equity!$N:$N,MATCH($B$2&"#"&12,Equity!$P:$P,0)),"")
A28: =IFERROR(INDEX(Equity!$B:$B,MATCH($B$2&"#"&13,Equity!$P:$P,0)),"") | B28: =IFERROR(INDEX(Equity!$C:$C,MATCH($B$2&"#"&13,Equity!$P:$P,0)),"") | C28: =IFERROR(INDEX(Equity!$D:$D,MATCH($B$2&"#"&13,Equity!$P:$P,0)),"") | D28: =IFERROR(INDEX(Equity!$E:$E,MATCH($B$2&"#"&13,Equity!$P:$P,0)),"") | E28: =IFERROR(INDEX(Equity!$I:$I,MATCH($B$2&"#"&13,Equity!$P:$P,0)),"") | F28: =IFERROR(INDEX(Equity!$K:$K,MATCH($B$2&"#"&13,Equity!$P:$P,0)),"") | G28: =IFERROR(INDEX(Equity!$N:$N,MATCH($B$2&"#"&13,Equity!$P:$P,0)),"")
A29: =IFERROR(INDEX(Equity!$B:$B,MATCH($B$2&"#"&14,Equity!$P:$P,0)),"") | B29: =IFERROR(INDEX(Equity!$C:$C,MATCH($B$2&"#"&14,Equity!$P:$P,0)),"") | C29: =IFERROR(INDEX(Equity!$D:$D,MATCH($B$2&"#"&14,Equity!$P:$P,0)),"") | D29: =IFERROR(INDEX(Equity!$E:$E,MATCH($B$2&"#"&14,Equity!$P:$P,0)),"") | E29: =IFERROR(INDEX(Equity!$I:$I,MATCH($B$2&"#"&14,Equity!$P:$P,0)),"") | F29: =IFERROR(INDEX(Equity!$K:$K,MATCH($B$2&"#"&14,Equity!$P:$P,0)),"") | G29: =IFERROR(INDEX(Equity!$N:$N,MATCH($B$2&"#"&14,Equity!$P:$P,0)),"")
A30: =IFERROR(INDEX(Equity!$B:$B,MATCH($B$2&"#"&15,Equity!$P:$P,0)),"") | B30: =IFERROR(INDEX(Equity!$C:$C,MATCH($B$2&"#"&15,Equity!$P:$P,0)),"") | C30: =IFERROR(INDEX(Equity!$D:$D,MATCH($B$2&"#"&15,Equity!$P:$P,0)),"") | D30: =IFERROR(INDEX(Equity!$E:$E,MATCH($B$2&"#"&15,Equity!$P:$P,0)),"") | E30: =IFERROR(INDEX(Equity!$I:$I,MATCH($B$2&"#"&15,Equity!$P:$P,0)),"") | F30: =IFERROR(INDEX(Equity!$K:$K,MATCH($B$2&"#"&15,Equity!$P:$P,0)),"") | G30: =IFERROR(INDEX(Equity!$N:$N,MATCH($B$2&"#"&15,Equity!$P:$P,0)),"")
A31: =IFERROR(INDEX(Equity!$B:$B,MATCH($B$2&"#"&16,Equity!$P:$P,0)),"") | B31: =IFERROR(INDEX(Equity!$C:$C,MATCH($B$2&"#"&16,Equity!$P:$P,0)),"") | C31: =IFERROR(INDEX(Equity!$D:$D,MATCH($B$2&"#"&16,Equity!$P:$P,0)),"") | D31: =IFERROR(INDEX(Equity!$E:$E,MATCH($B$2&"#"&16,Equity!$P:$P,0)),"") | E31: =IFERROR(INDEX(Equity!$I:$I,MATCH($B$2&"#"&16,Equity!$P:$P,0)),"") | F31: =IFERROR(INDEX(Equity!$K:$K,MATCH($B$2&"#"&16,Equity!$P:$P,0)),"") | G31: =IFERROR(INDEX(Equity!$N:$N,MATCH($B$2&"#"&16,Equity!$P:$P,0)),"")
A32: =IFERROR(INDEX(Equity!$B:$B,MATCH($B$2&"#"&17,Equity!$P:$P,0)),"") | B32: =IFERROR(INDEX(Equity!$C:$C,MATCH($B$2&"#"&17,Equity!$P:$P,0)),"") | C32: =IFERROR(INDEX(Equity!$D:$D,MATCH($B$2&"#"&17,Equity!$P:$P,0)),"") | D32: =IFERROR(INDEX(Equity!$E:$E,MATCH($B$2&"#"&17,Equity!$P:$P,0)),"") | E32: =IFERROR(INDEX(Equity!$I:$I,MATCH($B$2&"#"&17,Equity!$P:$P,0)),"") | F32: =IFERROR(INDEX(Equity!$K:$K,MATCH($B$2&"#"&17,Equity!$P:$P,0)),"") | G32: =IFERROR(INDEX(Equity!$N:$N,MATCH($B$2&"#"&17,Equity!$P:$P,0)),"")
A33: =IFERROR(INDEX(Equity!$B:$B,MATCH($B$2&"#"&18,Equity!$P:$P,0)),"") | B33: =IFERROR(INDEX(Equity!$C:$C,MATCH($B$2&"#"&18,Equity!$P:$P,0)),"") | C33: =IFERROR(INDEX(Equity!$D:$D,MATCH($B$2&"#"&18,Equity!$P:$P,0)),"") | D33: =IFERROR(INDEX(Equity!$E:$E,MATCH($B$2&"#"&18,Equity!$P:$P,0)),"") | E33: =IFERROR(INDEX(Equity!$I:$I,MATCH($B$2&"#"&18,Equity!$P:$P,0)),"") | F33: =IFERROR(INDEX(Equity!$K:$K,MATCH($B$2&"#"&18,Equity!$P:$P,0)),"") | G33: =IFERROR(INDEX(Equity!$N:$N,MATCH($B$2&"#"&18,Equity!$P:$P,0)),"")
A34: =IFERROR(INDEX(Equity!$B:$B,MATCH($B$2&"#"&19,Equity!$P:$P,0)),"") | B34: =IFERROR(INDEX(Equity!$C:$C,MATCH($B$2&"#"&19,Equity!$P:$P,0)),"") | C34: =IFERROR(INDEX(Equity!$D:$D,MATCH($B$2&"#"&19,Equity!$P:$P,0)),"") | D34: =IFERROR(INDEX(Equity!$E:$E,MATCH($B$2&"#"&19,Equity!$P:$P,0)),"") | E34: =IFERROR(INDEX(Equity!$I:$I,MATCH($B$2&"#"&19,Equity!$P:$P,0)),"") | F34: =IFERROR(INDEX(Equity!$K:$K,MATCH($B$2&"#"&19,Equity!$P:$P,0)),"") | G34: =IFERROR(INDEX(Equity!$N:$N,MATCH($B$2&"#"&19,Equity!$P:$P,0)),"")
A35: =IFERROR(INDEX(Equity!$B:$B,MATCH($B$2&"#"&20,Equity!$P:$P,0)),"") | B35: =IFERROR(INDEX(Equity!$C:$C,MATCH($B$2&"#"&20,Equity!$P:$P,0)),"") | C35: =IFERROR(INDEX(Equity!$D:$D,MATCH($B$2&"#"&20,Equity!$P:$P,0)),"") | D35: =IFERROR(INDEX(Equity!$E:$E,MATCH($B$2&"#"&20,Equity!$P:$P,0)),"") | E35: =IFERROR(INDEX(Equity!$I:$I,MATCH($B$2&"#"&20,Equity!$P:$P,0)),"") | F35: =IFERROR(INDEX(Equity!$K:$K,MATCH($B$2&"#"&20,Equity!$P:$P,0)),"") | G35: =IFERROR(INDEX(Equity!$N:$N,MATCH($B$2&"#"&20,Equity!$P:$P,0)),"")
A36: =IFERROR(INDEX(Equity!$B:$B,MATCH($B$2&"#"&21,Equity!$P:$P,0)),"") | B36: =IFERROR(INDEX(Equity!$C:$C,MATCH($B$2&"#"&21,Equity!$P:$P,0)),"") | C36: =IFERROR(INDEX(Equity!$D:$D,MATCH($B$2&"#"&21,Equity!$P:$P,0)),"") | D36: =IFERROR(INDEX(Equity!$E:$E,MATCH($B$2&"#"&21,Equity!$P:$P,0)),"") | E36: =IFERROR(INDEX(Equity!$I:$I,MATCH($B$2&"#"&21,Equity!$P:$P,0)),"") | F36: =IFERROR(INDEX(Equity!$K:$K,MATCH($B$2&"#"&21,Equity!$P:$P,0)),"") | G36: =IFERROR(INDEX(Equity!$N:$N,MATCH($B$2&"#"&21,Equity!$P:$P,0)),"")
A37: =IFERROR(INDEX(Equity!$B:$B,MATCH($B$2&"#"&22,Equity!$P:$P,0)),"") | B37: =IFERROR(INDEX(Equity!$C:$C,MATCH($B$2&"#"&22,Equity!$P:$P,0)),"") | C37: =IFERROR(INDEX(Equity!$D:$D,MATCH($B$2&"#"&22,Equity!$P:$P,0)),"") | D37: =IFERROR(INDEX(Equity!$E:$E,MATCH($B$2&"#"&22,Equity!$P:$P,0)),"") | E37: =IFERROR(INDEX(Equity!$I:$I,MATCH($B$2&"#"&22,Equity!$P:$P,0)),"") | F37: =IFERROR(INDEX(Equity!$K:$K,MATCH($B$2&"#"&22,Equity!$P:$P,0)),"") | G37: =IFERROR(INDEX(Equity!$N:$N,MATCH($B$2&"#"&22,Equity!$P:$P,0)),"")
A38: =IFERROR(INDEX(Equity!$B:$B,MATCH($B$2&"#"&23,Equity!$P:$P,0)),"") | B38: =IFERROR(INDEX(Equity!$C:$C,MATCH($B$2&"#"&23,Equity!$P:$P,0)),"") | C38: =IFERROR(INDEX(Equity!$D:$D,MATCH($B$2&"#"&23,Equity!$P:$P,0)),"") | D38: =IFERROR(INDEX(Equity!$E:$E,MATCH($B$2&"#"&23,Equity!$P:$P,0)),"") | E38: =IFERROR(INDEX(Equity!$I:$I,MATCH($B$2&"#"&23,Equity!$P:$P,0)),"") | F38: =IFERROR(INDEX(Equity!$K:$K,MATCH($B$2&"#"&23,Equity!$P:$P,0)),"") | G38: =IFERROR(INDEX(Equity!$N:$N,MATCH($B$2&"#"&23,Equity!$P:$P,0)),"")
A39: =IFERROR(INDEX(Equity!$B:$B,MATCH($B$2&"#"&24,Equity!$P:$P,0)),"") | B39: =IFERROR(INDEX(Equity!$C:$C,MATCH($B$2&"#"&24,Equity!$P:$P,0)),"") | C39: =IFERROR(INDEX(Equity!$D:$D,MATCH($B$2&"#"&24,Equity!$P:$P,0)),"") | D39: =IFERROR(INDEX(Equity!$E:$E,MATCH($B$2&"#"&24,Equity!$P:$P,0)),"") | E39: =IFERROR(INDEX(Equity!$I:$I,MATCH($B$2&"#"&24,Equity!$P:$P,0)),"") | F39: =IFERROR(INDEX(Equity!$K:$K,MATCH($B$2&"#"&24,Equity!$P:$P,0)),"") | G39: =IFERROR(INDEX(Equity!$N:$N,MATCH($B$2&"#"&24,Equity!$P:$P,0)),"")
A40: =IFERROR(INDEX(Equity!$B:$B,MATCH($B$2&"#"&25,Equity!$P:$P,0)),"") | B40: =IFERROR(INDEX(Equity!$C:$C,MATCH($B$2&"#"&25,Equity!$P:$P,0)),"") | C40: =IFERROR(INDEX(Equity!$D:$D,MATCH($B$2&"#"&25,Equity!$P:$P,0)),"") | D40: =IFERROR(INDEX(Equity!$E:$E,MATCH($B$2&"#"&25,Equity!$P:$P,0)),"") | E40: =IFERROR(INDEX(Equity!$I:$I,MATCH($B$2&"#"&25,Equity!$P:$P,0)),"") | F40: =IFERROR(INDEX(Equity!$K:$K,MATCH($B$2&"#"&25,Equity!$P:$P,0)),"") | G40: =IFERROR(INDEX(Equity!$N:$N,MATCH($B$2&"#"&25,Equity!$P:$P,0)),"")
A41: =IFERROR(INDEX(Equity!$B:$B,MATCH($B$2&"#"&26,Equity!$P:$P,0)),"") | B41: =IFERROR(INDEX(Equity!$C:$C,MATCH($B$2&"#"&26,Equity!$P:$P,0)),"") | C41: =IFERROR(INDEX(Equity!$D:$D,MATCH($B$2&"#"&26,Equity!$P:$P,0)),"") | D41: =IFERROR(INDEX(Equity!$E:$E,MATCH($B$2&"#"&26,Equity!$P:$P,0)),"") | E41: =IFERROR(INDEX(Equity!$I:$I,MATCH($B$2&"#"&26,Equity!$P:$P,0)),"") | F41: =IFERROR(INDEX(Equity!$K:$K,MATCH($B$2&"#"&26,Equity!$P:$P,0)),"") | G41: =IFERROR(INDEX(Equity!$N:$N,MATCH($B$2&"#"&26,Equity!$P:$P,0)),"")
A42: =IFERROR(INDEX(Equity!$B:$B,MATCH($B$2&"#"&27,Equity!$P:$P,0)),"") | B42: =IFERROR(INDEX(Equity!$C:$C,MATCH($B$2&"#"&27,Equity!$P:$P,0)),"") | C42: =IFERROR(INDEX(Equity!$D:$D,MATCH($B$2&"#"&27,Equity!$P:$P,0)),"") | D42: =IFERROR(INDEX(Equity!$E:$E,MATCH($B$2&"#"&27,Equity!$P:$P,0)),"") | E42: =IFERROR(INDEX(Equity!$I:$I,MATCH($B$2&"#"&27,Equity!$P:$P,0)),"") | F42: =IFERROR(INDEX(Equity!$K:$K,MATCH($B$2&"#"&27,Equity!$P:$P,0)),"") | G42: =IFERROR(INDEX(Equity!$N:$N,MATCH($B$2&"#"&27,Equity!$P:$P,0)),"")
A43: =IFERROR(INDEX(Equity!$B:$B,MATCH($B$2&"#"&28,Equity!$P:$P,0)),"") | B43: =IFERROR(INDEX(Equity!$C:$C,MATCH($B$2&"#"&28,Equity!$P:$P,0)),"") | C43: =IFERROR(INDEX(Equity!$D:$D,MATCH($B$2&"#"&28,Equity!$P:$P,0)),"") | D43: =IFERROR(INDEX(Equity!$E:$E,MATCH($B$2&"#"&28,Equity!$P:$P,0)),"") | E43: =IFERROR(INDEX(Equity!$I:$I,MATCH($B$2&"#"&28,Equity!$P:$P,0)),"") | F43: =IFERROR(INDEX(Equity!$K:$K,MATCH($B$2&"#"&28,Equity!$P:$P,0)),"") | G43: =IFERROR(INDEX(Equity!$N:$N,MATCH($B$2&"#"&28,Equity!$P:$P,0)),"")
...

Sheet Equity
A1: EQUITY HOLDINGS
A2: Enter Owner, then PICK the Scrip from the dropdown — ISIN fills itself from Stock_Master (type it only for delisted scrips). Enter Qty, Avg cost and Cost date (drives XIRR); prices refresh via UpdatePrices.bat. Grey columns compute themselves.
A3: Owner | B3: ISIN | C3: Scrip | D3: Quantity | E3: Avg. cost | F3: Closing Price | G3: Prev. close | H3: Closing Price Date | I3: Cur. val | J3: Invested | K3: Net chg. | L3: Day chg. | M3: Cost date | N3: XIRR | P3: Key
A4: Amit | B4: =IF($C4="","",IFERROR(INDEX(Stock_Master!$C:$C,MATCH($C4,Stock_Master!$B:$B,0)),"")) -> INE002A01018 | C4: RELIANCE INDUSTRIES LTD. | D4: 50 | E4: 964.9 | F4: 1520 | G4: 1512.3 | H4: 13-07-2026 | I4: =IF($D4="","",$D4*$F4) -> 76000 | J4: =IF(OR($D4="",$E4=""),"",$D4*$E4) -> 48245 | K4: =IF(OR($E4="",$D4=""),"",$I4-$J4) -> 27755 | L4: =IF(OR($G4="",$D4=""),"",$D4*($F4-$G4)) -> 385 | M4: 43131 | N4: =IF(OR($M4="",N($J4)=0,$I4="",TODAY()<=$M4),"",($I4/$J4)^(365/(TODAY()-$M4))-1) -> 0.055220257 | P4: =IF($A4="","",$A4&"#"&COUNTIF($A$4:$A4,$A4)) -> Amit#1
A5: Amit | B5: =IF($C5="","",IFERROR(INDEX(Stock_Master!$C:$C,MATCH($C5,Stock_Master!$B:$B,0)),"")) -> INE467B01029 | C5: TATA CONSULTANCY SERVICES LTD. | D5: 12 | E5: 2916.05 | F5: 3450 | G5: 3462.1 | H5: 13-07-2026 | I5: =IF($D5="","",$D5*$F5) -> 41400 | J5: =IF(OR($D5="",$E5=""),"",$D5*$E5) -> 34992.6 | K5: =IF(OR($E5="",$D5=""),"",$I5-$J5) -> 6407.4 | L5: =IF(OR($G5="",$D5=""),"",$D5*($F5-$G5)) -> -145.2 | M5: 43131 | N5: =IF(OR($M5="",N($J5)=0,$I5="",TODAY()<=$M5),"",($I5/$J5)^(365/(TODAY()-$M5))-1) -> 0.020086519 | P5: =IF($A5="","",$A5&"#"&COUNTIF($A$4:$A5,$A5)) -> Amit#2
A6: Amit | B6: =IF($C6="","",IFERROR(INDEX(Stock_Master!$C:$C,MATCH($C6,Stock_Master!$B:$B,0)),"")) -> INE009A01021 | C6: INFOSYS LTD. | D6: 40 | E6: 1173.85 | F6: 1610 | G6: 1598.7 | H6: 13-07-2026 | I6: =IF($D6="","",$D6*$F6) -> 64400 | J6: =IF(OR($D6="",$E6=""),"",$D6*$E6) -> 46954 | K6: =IF(OR($E6="",$D6=""),"",$I6-$J6) -> 17446 | L6: =IF(OR($G6="",$D6=""),"",$D6*($F6-$G6)) -> 452 | M6: 43131 | N6: =IF(OR($M6="",N($J6)=0,$I6="",TODAY()<=$M6),"",($I6/$J6)^(365/(TODAY()-$M6))-1) -> 0.038075757 | P6: =IF($A6="","",$A6&"#"&COUNTIF($A$4:$A6,$A6)) -> Amit#3
